Workbook
Name pivot: #REF!

Sheet INDUSTRY DATA
A1: SAP_Code | B1: Outlet Name | C1: Trading_Area_Name | D1: District | E1: Sales Area | F1: Company | G1: Latitude | H1: Longitude | I1: MS Apr 2024 | J1: HSD Apr 2024 | K1: MS May 2024 | L1: HSD May 2024 | M1: MS June 2024 | N1: HSD June 2024 | O1: MS July 2024 | P1: HSD July 2024 | Q1: MS Aug 2024 | R1: HSD Aug 2024 | S1: MS Sept 2024 | T1: HSD Sept 2024 | U1: MS Oct 2024 | V1: HSD Oct 2024 | W1: MS Nov 2024 | X1: HSD Nov 2024 | Y1: MS Dec 2024 | Z1: HSD Dec 2024 | AA1: MS Jan 2025 | AB1: HSD Jan 2025 | AC1: MS Feb 2025 | AD1: HSD Feb 2025 | AE1: MS Mar 2025 | AF1: HSD Mar 2025 | AG1: MS Apr 2025 | AH1: HSD Apr 2025 | AI1: MS May 2025 | AJ1: HSD May 2025 | AK1: MS June 2025 | AL1: HSD June 2025 | AM1: MS July 2025 | AN1: HSD July 2025 | AO1: MS Aug 2025 | AP1: HSD Aug 2025 | AQ1: MS Sept 2025 | AR1: HSD Sept 2025 | AS1: MS Oct 2025 | AT1: HSD Oct 2025 | AU1: MS Nov 2025 | AV1: HSD Nov 2025 | AW1: MS Dec 2025 | AX1: HSD Dec 2025 | AY1: MS Jan 2026 | AZ1: HSD Jan 2026 | BA1: MS Feb 2026 | BB1: HSD Feb 2026 | BC1: MS Mar 2026 | BD1: HSD Mar 2026 | BE1: MS Apr 2026 | BF1: HSD Apr 2026
A2: 41048256 | B2: SHRI AGRAWAL FUELS | C2: ECZ_Bemetara_Nandghat_Town | D2: BEMETARA | E2: Durg SA | F2: HPC | G2: 21.801585 | H2: 81.351672 | I2: 22 | J2: 18 | K2: 13 | L2: 25 | M2: 16 | N2: 32 | O2: 20 | P2: 4 | Q2: 8 | R2: 4 | S2: 16 | T2: 8 | U2: 12 | V2: 12 | W2: 16 | X2: 20 | Y2: 24 | Z2: 24 | AA2: 12 | AB2: 12 | AC2: 16 | AD2: 8 | AE2: 20 | AF2: 16 | AG2: 20 | AH2: 16 | AI2: 20 | AJ2: 28 | AK2: 15 | AL2: 27 | AM2: 16 | AN2: 8 | AO2: 24 | AP2: 12 | AQ2: 16 | AR2: 8 | AS2: 16 | AT2: 8 | AU2: 22 | AV2: 34 | AW2: 14 | AX2: 30 | AY2: 28 | AZ2: 8 | BA2: 12 | BB2: 12 | BC2: 18 | BD2: 22 | BE2: 25 | BF2: 13
A3: 41048297 | B3: KASAR FUELS | C3: ECZ_Bemetara_Bemetara_City_NH | D3: BEMETARA | E3: Durg SA | F3: HPC | G3: 21.70026 | H3: 81.522419 | I3: 65 | J3: 115 | K3: 55 | L3: 205 | M3: 70 | N3: 190 | O3: 55 | P3: 65 | Q3: 55 | R3: 45 | S3: 65 | T3: 55 | U3: 55 | V3: 85 | W3: 65 | X3: 215 | Y3: 65 | Z3: 175 | AA3: 55 | AB3: 85 | AC3: 75 | AD3: 125 | AE3: 70 | AF3: 110 | AG3: 65 | AH3: 155 | AI3: 70 | AJ3: 210 | AK3: 60 | AL3: 180 | AM3: 60 | AN3: 80 | AO3: 70 | AP3: 50 | AQ3: 65 | AR3: 55 | AS3: 75 | AT3: 65 | AU3: 50 | AV3: 210 | AW3: 70 | AX3: 170 | AY3: 70 | AZ3: 90 | BA3: 55 | BB3: 85 | BC3: 95 | BD3: 125 | BE3: 85 | BF3: 195
A4: 41048248 | B4: ADITYA FUELS | C4: ECZ_Bemetara_Berla_Town | D4: BEMETARA | E4: Durg SA | F4: HPC | G4: 21.624193 | H4: 81.376347 | I4: 13.5 | J4: 76.5 | K4: 13.5 | L4: 94.5 | M4: 9 | N4: 81 | O4: 18 | P4: 36 | Q4: 13.5 | R4: 22.5 | S4: 13.5 | T4: 22.5 | U4: 13.5 | V4: 40.5 | W4: 14 | X4: 78 | Y4: 22.5 | Z4: 103.5 | AA4: 14.5 | AB4: 61.5 | AC4: 13.5 | AD4: 76.5 | AE4: 22.5 | AF4: 67.5 | AG4: 9 | AH4: 63 | AI4: 26.5 | AJ4: 95.5 | AK4: 9 | AL4: 101 | AM4: 13.5 | AN4: 40.5 | AO4: 18 | AP4: 36 | AQ4: 13.5 | AR4: 22.5 | AS4: 18 | AT4: 36 | AU4: 13.5 | AV4: 58.5 | AW4: 13.5 | AX4: 76.5 | AY4: 9 | AZ4: 27 | BA4: 13.5 | BB4: 40.5 | BC4: 18 | BD4: 36 | BE4: 18 | BF4: 56
A5: 41047233 | B5: AMBA FUELS | C5: ECZ_Bemetara_Bemetara_City_NH | D5: BEMETARA | E5: Durg SA | F5: HPC | G5: 21.746697 | H5: 81.528584 | I5: 80 | J5: 160 | K5: 65 | L5: 155 | M5: 60 | N5: 140 | O5: 60 | P5: 80 | Q5: 60 | R5: 80 | S5: 45 | T5: 75 | U5: 65 | V5: 95 | W5: 65 | X5: 135 | Y5: 45 | Z5: 135 | AA5: 65 | AB5: 15 | AC5: 65 | AD5: 75 | AE5: 75 | AF5: 125 | AG5: 50 | AH5: 110 | AI5: 50 | AJ5: 110 | AK5: 60 | AL5: 140 | AM5: 65 | AN5: 75 | AO5: 65 | AP5: 55 | AQ5: 65 | AR5: 75 | AS5: 80 | AT5: 80 | AU5: 60 | AV5: 120 | AW5: 70 | AX5: 110 | AY5: 65 | AZ5: 95 | BA5: 60 | BB5: 80 | BC5: 80 | BD5: 120 | BE5: 75 | BF5: 125
A6: 41047376 | B6: JYOTI FUELS | C6: ECZ_Bemetara_Sanjari_Bhatapara_Road | D6: BEMETARA | E6: Durg SA | F6: HPC | G6: 21.52556 | H6: 81.486156 | I6: 31.5 | J6: 22.5 | K6: 35.5 | L6: 58.5 | M6: 30.5 | N6: 53.5 | O6: 27 | P6: 27 | Q6: 25.5 | R6: 4.5 | S6: 36 | T6: 12 | U6: 29 | V6: 21 | W6: 28 | X6: 60 | Y6: 35 | Z6: 63 | AA6: 36 | AB6: 36 | AC6: 28 | AD6: 20 | AE6: 38.5 | AF6: 17 | AG6: 40 | AH6: 20 | AI6: 27 | AJ6: 43 | AK6: 27 | AL6: 51.05 | AM6: 37 | AN6: 25 | AO6: 28 | AP6: 8 | AQ6: 40 | AR6: 8 | AS6: 36 | AT6: 12 | AU6: 31.03 | AV6: 59 | AW6: 41.5 | AX6: 48.53 | AY6: 33 | AZ6: 17 | BA6: 32.015 | BB6: 16 | BC6: 36 | BD6: 24 | BE6: 24 | BF6: 12
A7: 41016703 | B7: AVINASH FUELS | C7: ECZ_Bemetara_Simga_Kharora_South | D7: BEMETARA | E7: Durg SA | F7: HPC | G7: 21.396014 | H7: 81.578257 | I7: 27 | J7: 31 | K7: 32 | L7: 64 | M7: 32.5 | N7: 69.5 | O7: 36 | P7: 60 | Q7: 36 | R7: 24 | S7: 44 | T7: 16 | U7: 32 | V7: 28 | W7: 32 | X7: 52 | Y7: 36 | Z7: 60 | AA7: 28 | AB7: 32 | AC7: 32 | AD7: 16 | AE7: 32 | AF7: 28 | AG7: 12 | AH7: 12 | AI7: 8 | AJ7: 4 | AK7: 12 | AL7: 24 | AM7: 8 | AN7: 4 | AO7: 13 | AP7: 13 | AQ7: 8 | AR7: 4 | AS7: 12 | AT7: 12 | AU7: 14 | AV7: 18 | AW7: 8 | AX7: 4 | AY7: 8 | AZ7: 4 | BA7: 16 | BB7: 20 | BC7: 8 | BD7: 4 | BE7: 8 | BF7: 4
A8: 41016728 | B8: SHREE LAXMI PETROL PUMP | C8: ECZ_Bemetara_Thakurtola_Nawagarh_West | D8: BEMETARA | E8: Durg SA | F8: HPC | G8: 21.888885 | H8: 81.47097 | I8: 70 | J8: 90 | K8: 70 | L8: 130 | M8: 64 | N8: 164 | O8: 45 | P8: 15 | Q8: 55 | R8: 25 | S8: 60 | T8: 20 | U8: 60 | V8: 60 | W8: 65 | X8: 183 | Y8: 64 | Z8: 100 | AA8: 60 | AB8: 60 | AC8: 65 | AD8: 55 | AE8: 80 | AF8: 120 | AG8: 85 | AH8: 95 | AI8: 68 | AJ8: 119.02 | AK8: 58 | AL8: 144 | AM8: 60 | AN8: 40 | AO8: 45 | AP8: 15 | AQ8: 60 | AR8: 20 | AS8: 60 | AT8: 20 | AU8: 54 | AV8: 148 | AW8: 60 | AX8: 140 | AY8: 55 | AZ8: 45 | BA8: 65 | BB8: 55 | BC8: 75 | BD8: 85 | BE8: 75 | BF8: 65
A9: 41016746 | B9: SHREE LAXMI PETROL PUMP | C9: ECZ_Bemetara_Nawagarh_NH_North | D9: BEMETARA | E9: Durg SA | F9: HPC | G9: 21.893298 | H9: 81.615435 | I9: 70 | J9: 110 | K9: 50 | L9: 90 | M9: 45 | N9: 115 | O9: 50 | P9: 50 | Q9: 45 | R9: 35 | S9: 55 | T9: 25 | U9: 50 | V9: 70 | W9: 50 | X9: 130 | Y9: 45 | Z9: 115 | AA9: 60 | AB9: 80 | AC9: 60 | AD9: 60 | AE9: 55 | AF9: 65 | AG9: 60 | AH9: 80 | AI9: 45 | AJ9: 95 | AK9: 40 | AL9: 120 | AM9: 35 | AN9: 45 | AO9: 40 | AP9: 40 | AQ9: 35 | AR9: 25 | AS9: 35 | AT9: 45 | AU9: 40 | AV9: 120 | AW9: 45 | AX9: 115 | AY9: 35 | AZ9: 45 | BA9: 45 | BB9: 55 | BC9: 45 | BD9: 75 | BE9: 45 | BF9: 75
A10: 41015475 | B10: ARYAN FUELS | C10: ECZ_Bemetara_Nandghat_Town | D10: BEMETARA | E10: Durg SA | F10: HPC | G10: 21.807338 | H10: 81.33534 | I10: 53 | J10: 47 | K10: 50 | L10: 90 | M10: 45 | N10: 115 | O10: 41 | P10: 15 | Q10: 45 | R10: 15 | S10: 42 | T10: 10 | U10: 55 | V10: 45 | W10: 44.5 | X10: 93.5 | Y10: 40 | Z10: 60 | AA10: 35 | AB10: 25 | AC10: 30 | AD10: 30 | AE10: 47 | AF10: 37 | AG10: 45 | AH10: 35 | AI10: 45 | AJ10: 75 | AK10: 35 | AL10: 85 | AM10: 37 | AN10: 15 | AO10: 45 | AP10: 15 | AQ10: 45 | AR10: 15 | AS10: 30 | AT10: 10 | AU10: 40 | AV10: 60 | AW10: 40 | AX10: 80 | AY10: 49 | AZ10: 25 | BA10: 35 | BB10: 25 | BC10: 45.01 | BD10: 35 | BE10: 45 | BF10: 55
A11: 41015477 | B11: SATYANARAYAN PETROLEUM | C11: ECZ_Bemetara_Khairagarh_Road_East | D11: BEMETARA | E11: Durg SA | F11: HPC | G11: 21.801085 | H11: 81.862071 | I11: 27 | J11: 31 | K11: 9 | L11: 5 | M11: 19 | N11: 45 | O11: 22 | P11: 32 | Q11: 17 | R11: 9 | S11: 13 | T11: 17 | U11: 25 | V11: 13 | W11: 0 | X11: 0 | Y11: 19 | Z11: 27 | AA11: 5 | AB11: 9 | AC11: 17 | AD11: 9 | AE11: 18 | AF11: 18 | AG11: 19 | AH11: 27 | AI11: 30 | AJ11: 48 | AK11: 20 | AL11: 28 | AM11: 24.01 | AN11: 24.02 | AO11: 16 | AP11: 8 | AQ11: 16 | AR11: 8 | AS11: 16 | AT11: 8 | AU11: 15 | AV11: 5 | AW11: 26 | AX11: 26 | AY11: 27 | AZ11: 19 | BA11: 8 | BB11: 4 | BC11: 20 | BD11: 16 | BE11: 8 | BF11: 16
A12: 41015488 | B12: BAGHEL FUELS | C12: ECZ_Bemetara_Nawagarh_East_Corridor | D12: BEMETARA | E12: Durg SA | F12: HPC | G12: 21.907956 | H12: 81.747464 | I12: 60 | J12: 104 | K12: 54 | L12: 194 | M12: 40 | N12: 160 | O12: 50 | P12: 70 | Q12: 45 | R12: 15 | S12: 45 | T12: 15 | U12: 45 | V12: 55 | W12: 48 | X12: 194 | Y12: 55 | Z12: 185 | AA12: 70 | AB12: 90 | AC12: 55 | AD12: 85 | AE12: 65 | AF12: 95 | AG12: 45 | AH12: 95 | AI12: 40 | AJ12: 160 | AK12: 35 | AL12: 125 | AM12: 39 | AN12: 39 | AO12: 55 | AP12: 25 | AQ12: 45 | AR12: 35 | AS12: 30 | AT12: 30 | AU12: 45 | AV12: 135 | AW12: 55 | AX12: 165 | AY12: 45 | AZ12: 55 | BA12: 55 | BB12: 65 | BC12: 60 | BD12: 84 | BE12: 35 | BF12: 65
A13: 41015816 | B13: DAU PURANLAL FUELS | C13: ECZ_Bemetara_Sanjari_South_NH | D13: BEMETARA | E13: Durg SA | F13: HPC | G13: 21.57138 | H13: 81.55744 | I13: 55 | J13: 45 | K13: 30 | L13: 70 | M13: 39.5 | N13: 78.5 | O13: 40 | P13: 40 | Q13: 40 | R13: 20 | S13: 40 | T13: 20 | U13: 43.5 | V13: 34.5 | W13: 40 | X13: 100 | Y13: 39 | Z13: 119 | AA13: 40 | AB13: 100 | AC13: 40 | AD13: 80 | AE13: 45 | AF13: 50 | AG13: 44 | AH13: 40 | AI13: 40 | AJ13: 80 | AK13: 40 | AL13: 80 | AM13: 35 | AN13: 45 | AO13: 50 | AP13: 30 | AQ13: 40 | AR13: 20 | AS13: 55 | AT13: 25 | AU13: 35 | AV13: 105 | AW13: 40 | AX13: 100 | AY13: 40 | AZ13: 60 | BA13: 40 | BB13: 60 | BC13: 60 | BD13: 60 | BE13: 54.5 | BF13: 63.5
... A84: 41032979 | B84: GUPTA FUELS | C84: ECZ_Durg_Durg_West_NH30 | D84: DURG | E84: Durg SA | F84: HPC | G84: 21.252343 | H84: 81.219862 | I84: 32 | J84: 26 | K84: 33 | L84: 29 | M84: 31 | N84: 35 | O84: 34 | P84: 30 | Q84: 32 | R84: 16 | S84: 36 | T84: 12 | U84: 40 | V84: 20 | W84: 32 | X84: 28 | Y84: 28 | Z84: 20 | AA84: 44 | AB84: 28 | AC84: 36 | AD84: 12 | AE84: 45 | AF84: 24 | AG84: 32 | AH84: 16 | AI84: 29 | AJ84: 21 | AK84: 36 | AL84: 36 | AM84: 34 | AN84: 18 | AO84: 24 | AP84: 12 | AQ84: 36 | AR84: 12 | AS84: 30.018 | AT84: 8.005 | AU84: 26.005 | AV84: 30 | AW84: 32 | AX84: 28 | AY84: 24 | AZ84: 12 | BA84: 33 | BB84: 17 | BC84: 33 | BD84: 17 | BE84: 12 | BF84: 12
A85: 41073677 | B85: AMRAVATI FUELS | C85: ECZ_Durg_Bhilai_Charoda_NE | D85: DURG | E85: Durg SA | F85: HPC | G85: 21.298097 | H85: 81.477672 | Y85: 0 | Z85: 4 | AA85: 0 | AB85: 0 | AC85: 0 | AD85: 0 | AE85: 0 | AF85: 0 | AG85: 5 | AH85: 15 | AI85: 25 | AJ85: 35 | AK85: 19.5 | AL85: 58.5 | AM85: 10 | AN85: 30 | AO85: 25 | AP85: 55 | AQ85: 20 | AR85: 40 | AS85: 20 | AT85: 60 | AU85: 20 | AV85: 60 | AW85: 20 | AX85: 60 | AY85: 15 | AZ85: 65 | BA85: 25 | BB85: 75 | BC85: 20 | BD85: 60 | BE85: 25 | BF85: 75
A86: 41075761 | B86: NIMESHA ENERGIES | C86: ECZ_Durg_NH53_Bhilai_East | D86: DURG | E86: Durg SA | F86: HPC | G86: 21.232511 | H86: 81.485261 | AA86: 0 | AB86: 4.5 | AC86: 0 | AD86: 0 | AE86: 9 | AF86: 9 | AG86: 12 | AH86: 0 | AI86: 20 | AJ86: 24 | AK86: 18 | AL86: 18 | AM86: 20 | AN86: 20 | AO86: 17 | AP86: 45 | AQ86: 27 | AR86: 51 | AS86: 26.5 | AT86: 69.5 | AU86: 31 | AV86: 97 | AW86: 24.5 | AX86: 67.5 | AY86: 30 | AZ86: 44 | BA86: 20 | BB86: 40 | BC86: 40 | BD86: 68 | BE86: 25 | BF86: 65
A87: 41077769 | B87: SATYAM POWERS | C87: ECZ_Durg_Durg_City_West | D87: DURG | E87: Durg SA | F87: HPC | G87: 21.184431 | H87: 81.263164 | AE87: 0 | AF87: 4.5 | AG87: 0 | AH87: 0 | AI87: 0 | AJ87: 0 | AK87: 0 | AL87: 0 | AM87: 0 | AN87: 0 | AO87: 12 | AP87: 0 | AQ87: 38 | AR87: 14 | AS87: 39.05 | AT87: 5 | AU87: 72.05 | AV87: 28.02 | AW87: 53 | AX87: 37 | AY87: 65 | AZ87: 71 | BA87: 57 | BB87: 91 | BC87: 53.021 | BD87: 65.034 | BE87: 48.01 | BF87: 82.01
A88: 41084754 | B88: AASHIRWAD HP | C88: ECZ_Durg_Raipur_Road_Corridor | D88: DURG | E88: Durg SA | F88: HPC | G88: 21.194431 | H88: 81.649935 | AE88: 0 | AF88: 4.5 | AG88: 0 | AH88: 0 | AI88: 0 | AJ88: 0 | AK88: 0 | AL88: 0 | AM88: 0 | AN88: 0 | AO88: 0 | AP88: 0 | AQ88: 0 | AR88: 0 | AS88: 0 | AT88: 0 | AU88: 15 | AV88: 5 | AW88: 10 | AX88: 10 | AY88: 35 | AZ88: 5 | BA88: 19 | BB88: 15 | BC88: 40 | BD88: 20 | BE88: 43.5 | BF88: 34.5
A89: 41053474 | B89: CHAWLA ENTERPRISES | C89: ECZ_Raipur_Airport_Road_Corridor | D89: RAIPUR | E89: Raipur-1 SA | F89: HPC | G89: 21.22864 | H89: 81.77548 | I89: 65 | J89: 235 | K89: 55 | L89: 249 | M89: 60 | N89: 240 | O89: 59 | P89: 239 | Q89: 57.5 | R89: 176.5 | S89: 54 | T89: 190 | U89: 63 | V89: 193 | W89: 73 | X89: 185 | Y89: 60 | Z89: 220 | AA89: 54.5 | AB89: 243.5 | AC89: 64.5 | AD89: 193.5 | AE89: 60 | AF89: 180 | AG89: 74.5 | AH89: 208.5 | AI89: 74.5 | AJ89: 187.5 | AK89: 64.5 | AL89: 173.5 | AM89: 55 | AN89: 165 | AO89: 60 | AP89: 160 | AQ89: 55 | AR89: 145 | AS89: 65 | AT89: 155 | AU89: 60 | AV89: 160 | AW89: 60 | AX89: 200 | AY89: 75 | AZ89: 185 | BA89: 63 | BB89: 151 | BC89: 69.5 | BD89: 168.5 | BE89: 70 | BF89: 190
A90: 41052224 | B90: ANOOP AUTO SERVICES | C90: ECZ_Raipur_City_Centre_Station_Road | D90: RAIPUR | E90: Raipur-1 SA | F90: HPC | G90: 21.24576 | H90: 81.64059 | I90: 21.5 | J90: 8.5 | K90: 58 | L90: 28 | M90: 64 | N90: 24 | O90: 52 | P90: 20 | Q90: 65.5 | R90: 24.5 | S90: 48.5 | T90: 17.5 | U90: 60 | V90: 20 | W90: 15 | X90: 5 | Y90: 64.5 | Z90: 21.5 | AA90: 61.5 | AB90: 16.5 | AC90: 35 | AD90: 9 | AE90: 40.5 | AF90: 13.5 | AG90: 62 | AH90: 18 | AI90: 45 | AJ90: 15 | AK90: 53.5 | AL90: 16.5 | AM90: 57 | AN90: 15 | AO90: 45 | AP90: 15 | AQ90: 30 | AR90: 10 | AS90: 55 | AT90: 19 | AU90: 45 | AV90: 15 | AW90: 58 | AX90: 18 | AY90: 61 | AZ90: 23 | BA90: 52 | BB90: 18 | BC90: 55 | BD90: 19 | BE90: 38 | BF90: 22
A91: 41052227 | B91: B S BHATIA & CO | C91: ECZ_Raipur_Telibandha_South_City | D91: RAIPUR | E91: Raipur-1 SA | F91: HPC | G91: 21.209037 | H91: 81.668502 | I91: 53.5 | J91: 44.5 | K91: 45 | L91: 35 | M91: 51 | N91: 39 | O91: 63 | P91: 35 | Q91: 51 | R91: 37 | S91: 56 | T91: 40 | U91: 56 | V91: 40 | W91: 44 | X91: 30 | Y91: 57 | Z91: 35 | AA91: 53.5 | AB91: 24.5 | AC91: 58.5 | AD91: 35.5 | AE91: 42 | AF91: 24 | AG91: 49 | AH91: 25 | AI91: 55 | AJ91: 33 | AK91: 56 | AL91: 28 | AM91: 58 | AN91: 34 | AO91: 49 | AP91: 25 | AQ91: 52 | AR91: 24 | AS91: 46.5 | AT91: 21.5 | AU91: 42 | AV91: 20 | AW91: 55.5 | AX91: 28.5 | AY91: 53 | AZ91: 29 | BA91: 26 | BB91: 12 | BC91: 46.5 | BD91: 25.5 | BE91: 48 | BF91: 32
A92: 41052149 | B92: LUNKAD SERVICE STATION | C92: ECZ_Raipur_NH130A_Urla_West | D92: RAIPUR | E92: Raipur-1 SA | F92: HPC | G92: 21.2675 | H92: 81.5808 | I92: 51 | J92: 187 | K92: 57 | L92: 159 | M92: 57 | N92: 159 | O92: 41 | P92: 151 | Q92: 57 | R92: 179 | S92: 60 | T92: 132 | U92: 64 | V92: 150 | W92: 47 | X92: 121 | Y92: 60 | Z92: 154 | AA92: 56 | AB92: 154 | AC92: 53 | AD92: 143 | AE92: 53 | AF92: 157 | AG92: 63 | AH92: 157 | AI92: 61 | AJ92: 159 | AK92: 64 | AL92: 151 | AM92: 65 | AN92: 150 | AO92: 64.01 | AP92: 124.01 | AQ92: 68 | AR92: 144 | AS92: 67 | AT92: 125 | AU92: 67 | AV92: 120 | AW92: 56 | AX92: 135 | AY92: 60 | AZ92: 135 | BA92: 60 | BB92: 133 | BC92: 82 | BD92: 158 | BE92: 74 | BF92: 175
A93: 41050787 | B93: MS SERVICE STATION | C93: ECZ_Raipur_GE_Road_Raipur_Central | D93: RAIPUR | E93: Raipur-1 SA | F93: HPC | G93: 21.23718 | H93: 81.68916 | I93: 74.5 | J93: 91.5 | K93: 80 | L93: 88 | M93: 65 | N93: 79 | O93: 83 | P93: 93 | Q93: 72.5 | R93: 81.5 | S93: 72.5 | T93: 81.5 | U93: 84 | V93: 98 | W93: 75 | X93: 93 | Y93: 78.5 | Z93: 101.5 | AA93: 80 | AB93: 100 | AC93: 72.5 | AD93: 87.5 | AE93: 68 | AF93: 90 | AG93: 73 | AH93: 63 | AI93: 82 | AJ93: 88 | AK93: 68 | AL93: 64 | AM93: 73.5 | AN93: 64.5 | AO93: 82 | AP93: 66 | AQ93: 86 | AR93: 68 | AS93: 80 | AT93: 62 | AU93: 75 | AV93: 85 | AW93: 66 | AX93: 53 | AY93: 72 | AZ93: 63 | BA93: 65 | BB93: 57 | BC93: 64 | BD93: 60 | BE93: 59.5 | BF93: 78.5
A94: 41049759 | B94: VEENU SERVICE STATION | C94: ECZ_Raipur_GE_Road_Tatibandh_North | D94: RAIPUR | E94: Raipur-1 SA | F94: HPC | G94: 21.30886 | H94: 81.63623 | I94: 195 | J94: 497 | K94: 190 | L94: 574 | M94: 199 | N94: 543 | O94: 190 | P94: 554 | Q94: 190 | R94: 510 | S94: 194 | T94: 470 | U94: 225 | V94: 479 | W94: 175 | X94: 425 | Y94: 185 | Z94: 435 | AA94: 200 | AB94: 484 | AC94: 180 | AD94: 444 | AE94: 185 | AF94: 455 | AG94: 198.5 | AH94: 443.5 | AI94: 190 | AJ94: 450 | AK94: 180 | AL94: 440 | AM94: 197 | AN94: 429 | AO94: 205 | AP94: 415 | AQ94: 205 | AR94: 419 | AS94: 205 | AT94: 375 | AU94: 183 | AV94: 399 | AW94: 195 | AX94: 489 | AY94: 205 | AZ94: 451 | BA94: 190 | BB94: 394 | BC94: 209 | BD94: 378 | BE94: 197 | BF94: 394
A95: 41048910 | B95: SHARDA SERVICE STATION | C95: ECZ_Raipur_City_Centre_Pandri | D95: RAIPUR | E95: Raipur-1 SA | F95: HPC | G95: 21.22097 | H95: 81.649232 | I95: 0 | J95: 0 | K95: 0 | L95: 0 | M95: 0 | N95: 0 | O95: 0 | P95: 0 | Q95: 0 | R95: 0 | S95: 0 | T95: 0 | U95: 0 | V95: 0 | W95: 0 | X95: 0 | Y95: 0 | Z95: 0 | AA95: 0 | AB95: 0 | AC95: 0 | AD95: 0 | AE95: 0 | AF95: 0 | AG95: 0 | AH95: 0 | AI95: 0 | AJ95: 0 | AK95: 0 | AL95: 0 | AM95: 0 | AN95: 0 | AO95: 0 | AP95: 0 | AQ95: 0 | AR95: 0 | AS95: 0 | AT95: 0 | AU95: 0 | AV95: 0 | AW95: 0 | AX95: 0 | AY95: 0 | AZ95: 0 | BA95: 0 | BB95: 0 | BC95: 0 | BD95: 0 | BE95: 0 | BF95: 0
A96: 41043381 | B96: JAIN AUTO SERVICE | C96: ECZ_Raipur_NH130A_Urla_West | D96: RAIPUR | E96: Raipur-1 SA | F96: HPC | G96: 21.25833 | H96: 81.56682 | I96: 9 | J96: 153 | K96: 17.5 | L96: 158.5 | M96: 23 | N96: 161 | O96: 17 | P96: 151 | Q96: 17 | R96: 137 | S96: 18 | T96: 118 | U96: 21.5 | V96: 180.5 | W96: 13 | X96: 113 | Y96: 22 | Z96: 194 | AA96: 22 | AB96: 174 | AC96: 12 | AD96: 160 | AE96: 22 | AF96: 167 | AG96: 21 | AH96: 160 | AI96: 20 | AJ96: 154 | AK96: 20.5 | AL96: 173.5 | AM96: 20 | AN96: 141 | AO96: 20 | AP96: 124 | AQ96: 24 | AR96: 121 | AS96: 20 | AT96: 110 | AU96: 20 | AV96: 146 | AW96: 21.5 | AX96: 144.5 | AY96: 21.5 | AZ96: 138.5 | BA96: 24 | BB96: 114 | BC96: 17 | BD96: 81 | BE96: 22 | BF96: 116
A97: 41043768 | B97: MS CHAWLA SERVICE STATION | C97: ECZ_Raipur_City_Centre_Station_Road | D97: RAIPUR | E97: Raipur-1 SA | F97: HPC | G97: 21.24588 | H97: 81.64157 | I97: 126 | J97: 0 | K97: 142 | L97: 0 | M97: 148 | N97: 0 | O97: 146 | P97: 0 | Q97: 144 | R97: 0 | S97: 134 | T97: 0 | U97: 164 | V97: 0 | W97: 146 | X97: 0 | Y97: 124 | Z97: 0 | AA97: 150 | AB97: 0 | AC97: 136 | AD97: 0 | AE97: 156 | AF97: 0 | AG97: 147 | AH97: 0 | AI97: 142 | AJ97: 0 | AK97: 140 | AL97: 0 | AM97: 154 | AN97: 0 | AO97: 160 | AP97: 0 | AQ97: 161 | AR97: 0 | AS97: 150 | AT97: 0 | AU97: 148 | AV97: 0 | AW97: 142 | AX97: 0 | AY97: 154 | AZ97: 0 | BA97: 132 | BB97: 0 | BC97: 156 | BD97: 0 | BE97: 137 | BF97: 0
A98: 41044127 | B98: MINOCHA AND COMPANY | C98: ECZ_Raipur_City_Centre_Pandri | D98: RAIPUR | E98: Raipur-1 SA | F98: HPC | G98: 21.239125 | H98: 81.675456 | I98: 336 | J98: 534 | K98: 316 | L98: 511 | M98: 340 | N98: 559 | O98: 329 | P98: 425 | Q98: 356 | R98: 514 | S98: 316 | T98: 438 | U98: 403 | V98: 525 | W98: 313 | X98: 484 | Y98: 336 | Z98: 418 | AA98: 343 | AB98: 324 | AC98: 305 | AD98: 275 | AE98: 331 | AF98: 278 | AG98: 372 | AH98: 324 | AI98: 337 | AJ98: 272 | AK98: 347 | AL98: 291 | AM98: 346 | AN98: 234 | AO98: 344 | AP98: 236 | AQ98: 350 | AR98: 230 | AS98: 377 | AT98: 232 | AU98: 349 | AV98: 376 | AW98: 376 | AX98: 436 | AY98: 345 | AZ98: 322 | BA98: 330 | BB98: 250 | BC98: 364 | BD98: 245 | BE98: 341 | BF98: 239
A99: 41048254 | B99: AASTHA PETROL PUMP (JAIL PUMP) | C99: ECZ_Raipur_City_Centre_Station_Road | D99: RAIPUR | E99: Raipur-1 SA | F99: HPC | G99: 21.251845 | H99: 81.64101 | I99: 58 | J99: 12 | K99: 71 | L99: 19 | M99: 57 | N99: 15 | O99: 49 | P99: 15 | Q99: 87.5 | R99: 14.5 | S99: 60 | T99: 20 | U99: 64 | V99: 20 | W99: 90 | X99: 19 | Y99: 58.5 | Z99: 19.5 | AA99: 64 | AB99: 20 | AC99: 62.5 | AD99: 19.5 | AE99: 79 | AF99: 25 | AG99: 45 | AH99: 15 | AI99: 63.06 | AJ99: 19.015 | AK99: 60 | AL99: 20 | AM99: 65 | AN99: 15 | AO99: 60 | AP99: 20 | AQ99: 64 | AR99: 20 | AS99: 53 | AT99: 15 | AU99: 39.091 | AV99: 5 | AW99: 54.05 | AX99: 10.025 | AY99: 26 | AZ99: 0 | BA99: 12 | BB99: 0 | BC99: 24 | BD99: 12 | BE99: 41 | BF99: 21
A100: 41048293 | B100: SAI BABA FILLING STATION | C100: ECZ_Raipur_City_Centre_Fafadih | D100: RAIPUR | E100: Raipur-1 SA | F100: HPC | G100: 21.26318 | H100: 81.65942 | I100: 145 | J100: 79 | K100: 170 | L100: 90 | M100: 175 | N100: 85 | O100: 165 | P100: 75 | Q100: 165 | R100: 75 | S100: 155 | T100: 65 | U100: 175 | V100: 85 | W100: 160 | X100: 100 | Y100: 165 | Z100: 75 | AA100: 150 | AB100: 90 | AC100: 160 | AD100: 80 | AE100: 155 | AF100: 85 | AG100: 175 | AH100: 65 | AI100: 190 | AJ100: 90 | AK100: 160 | AL100: 80 | AM100: 170 | AN100: 70 | AO100: 165 | AP100: 59 | AQ100: 180 | AR100: 80 | AS100: 160 | AT100: 60 | AU100: 180 | AV100: 60 | AW100: 140 | AX100: 60 | AY100: 155 | AZ100: 45 | BA100: 155 | BB100: 65 | BC100: 135 | BD100: 45 | BE100: 134 | BF100: 70
... A174: 41071990 | B174: MAA KARNI ENERGY POINT | C174: ECZ_Raipur_NH53_Bhatapara | D174: RAIPUR | E174: Raipur-1 SA | F174: HPC | G174: 21.494672 | H174: 81.696753 | I174: 0 | J174: 0 | K174: 0 | L174: 0 | M174: 0 | N174: 0 | O174: 0 | P174: 0 | Q174: 0 | R174: 0 | S174: 0 | T174: 0 | U174: 0 | V174: 0 | W174: 0 | X174: 0 | Y174: 8 | Z174: 4 | AA174: 0 | AB174: 0 | AC174: 0 | AD174: 0 | AE174: 17 | AF174: 13 | AG174: 26 | AH174: 22 | AI174: 17 | AJ174: 37 | AK174: 22.5 | AL174: 43.5 | AM174: 19 | AN174: 19 | AO174: 29 | AP174: 13 | AQ174: 21.5 | AR174: 8.5 | AS174: 28 | AT174: 8 | AU174: 17 | AV174: 39 | AW174: 30 | AX174: 50 | AY174: 30 | AZ174: 30 | BA174: 15 | BB174: 25 | BC174: 40 | BD174: 20 | BE174: 15 | BF174: 25
A175: 41076157 | B175: SHRI GOVIND JYOTI ENERGY POINT | C175: ECZ_Raipur_Mandir_Hasaud_Ring_Road | D175: RAIPUR | E175: Raipur-1 SA | F175: HPC | G175: 21.311819 | H175: 81.778888 | Y175: 0 | Z175: 4 | AA175: 0 | AB175: 0 | AC175: 0 | AD175: 0 | AE175: 0 | AF175: 0 | AG175: 0 | AH175: 0 | AI175: 0 | AJ175: 0 | AK175: 0 | AL175: 0 | AM175: 0 | AN175: 0 | AO175: 0 | AP175: 0 | AQ175: 0 | AR175: 0 | AS175: 0 | AT175: 0 | AU175: 0 | AV175: 0 | AW175: 8 | AX175: 4 | AY175: 0 | AZ175: 0 | BA175: 16 | BB175: 8 | BC175: 22 | BD175: 10 | BE175: 12 | BF175: 12
A176: 41077773 | B176: AARADHYA ENERGY POINT | C176: ECZ_Raipur_NH130A_Urla_West | D176: RAIPUR | E176: Raipur-1 SA | F176: HPC | G176: 21.216473 | H176: 81.592685 | AE176: 0 | AF176: 4 | AG176: 0 | AH176: 0 | AI176: 8 | AJ176: 4 | AK176: 23 | AL176: 9 | AM176: 40 | AN176: 20 | AO176: 33 | AP176: 17 | AQ176: 41 | AR176: 21 | AS176: 41.5 | AT176: 12.5 | AU176: 39 | AV176: 31 | AW176: 37 | AX176: 23 | AY176: 38 | AZ176: 38 | BA176: 44 | BB176: 40 | BC176: 51 | BD176: 35 | BE176: 35 | BF176: 19
A177: 41075903 | B177: SHYAM ENERGY POINT | C177: ECZ_Raipur_NH53_Simga_East | D177: RAIPUR | E177: Raipur-1 SA | F177: HPC | G177: 21.566002 | H177: 81.806231 | AE177: 0 | AF177: 4 | AG177: 0 | AH177: 0 | AI177: 13 | AJ177: 23 | AK177: 24 | AL177: 24 | AM177: 46 | AN177: 34 | AO177: 38 | AP177: 28 | AQ177: 44 | AR177: 24 | AS177: 44 | AT177: 24 | AU177: 44 | AV177: 38 | AW177: 41 | AX177: 59 | AY177: 37 | AZ177: 45 | BA177: 44 | BB177: 50 | BC177: 43 | BD177: 49 | BE177: 42 | BF177: 54
A178: 41044667 | B178: DINSHA FUELS | C178: ECZ_Raipur_City_Centre_Fafadih | D178: RAIPUR | E178: Raipur-1 SA | F178: HPC | G178: 21.256652 | H178: 81.658272 | AU178: 8 | AV178: 4 | AW178: 0 | AX178: 0 | AY178: 0 | AZ178: 0 | BA178: 0 | BB178: 0 | BC178: 72.5 | BD178: 19.5 | BE178: 110.5 | BF178: 19.5
A179: 41085397 | B179: MAULI ENERGY POINT | C179: ECZ_Raipur_Telibandha_South_City | D179: RAIPUR | E179: Raipur-1 SA | F179: HPC | G179: 21.194431 | H179: 81.649935 | AW179: 0 | AX179: 5 | AY179: 10 | AZ179: 0 | BA179: 19 | BB179: 5 | BC179: 94 | BD179: 42 | BE179: 143.5 | BF179: 74.5
A180: 41048269 | B180: SHANTI SERVICE STATION | C180: ECZ_Raipur_NH30_RHS_Abhanpur | D180: RAIPUR | E180: Raipur-II SA | F180: HPC | G180: 21.08503 | H180: 81.66084 | I180: 69 | J180: 75 | K180: 64 | L180: 100 | M180: 54 | N180: 130 | O180: 65 | P180: 95 | Q180: 63 | R180: 65 | S180: 48 | T180: 84 | U180: 65.5 | V180: 68.5 | W180: 49 | X180: 95 | Y180: 68 | Z180: 114 | AA180: 58 | AB180: 90 | AC180: 62 | AD180: 84 | AE180: 68.5 | AF180: 81.5 | AG180: 64.5 | AH180: 93.5 | AI180: 69 | AJ180: 125 | AK180: 60 | AL180: 120 | AM180: 50 | AN180: 70 | AO180: 60 | AP180: 80 | AQ180: 55 | AR180: 85 | AS180: 60 | AT180: 80 | AU180: 55 | AV180: 125 | AW180: 64.5 | AX180: 133.5 | AY180: 60 | AZ180: 120 | BA180: 60 | BB180: 100 | BC180: 55 | BD180: 105 | BE180: 55 | BF180: 125
A181: 41033197 | B181: MOTICHAND CHULLANY AND SONS | C181: ECZ_Raipur_Nava_Raipur_South_Bypass | D181: RAIPUR | E181: Raipur-II SA | F181: HPC | G181: 20.97226 | H181: 81.855196 | I181: 70 | J181: 90 | K181: 85 | L181: 135 | M181: 80 | N181: 100 | O181: 64.5 | P181: 73.5 | Q181: 89 | R181: 65 | S181: 80 | T181: 60 | U181: 85 | V181: 75 | W181: 80 | X181: 100 | Y181: 80 | Z181: 100 | AA181: 90 | AB181: 130 | AC181: 90 | AD181: 110 | AE181: 80 | AF181: 100 | AG181: 80 | AH181: 100 | AI181: 95 | AJ181: 105 | AK181: 75 | AL181: 105 | AM181: 80 | AN181: 80 | AO181: 90 | AP181: 70 | AQ181: 85 | AR181: 75 | AS181: 95 | AT181: 65 | AU181: 75 | AV181: 85 | AW181: 85 | AX181: 95 | AY181: 90 | AZ181: 110 | BA181: 85 | BB181: 135 | BC181: 75 | BD181: 105 | BE181: 80 | BF181: 140
A182: 41055536 | B182: AASTHA FUELS | C182: ECZ_Raipur_Nava_Raipur_NRDA | D182: RAIPUR | E182: Raipur-II SA | F182: HPC | G182: 21.0853 | H182: 81.8905 | I182: 62 | J182: 56 | K182: 67 | L182: 95 | M182: 57.5 | N182: 110.5 | O182: 58 | P182: 54 | Q182: 59 | R182: 43 | S182: 60 | T182: 34 | U182: 50 | V182: 54 | W182: 45 | X182: 91 | Y182: 69 | Z182: 91 | AA182: 58 | AB182: 60 | AC182: 63 | AD182: 49 | AE182: 54 | AF182: 58 | AG182: 67 | AH182: 103 | AI182: 30 | AJ182: 62 | AK182: 54 | AL182: 154 | AM182: 55 | AN182: 45 | AO182: 60 | AP182: 40 | AQ182: 53 | AR182: 29 | AS182: 52 | AT182: 54 | AU182: 50 | AV182: 108 | AW182: 55 | AX182: 63 | AY182: 40 | AZ182: 40 | BA182: 40 | BB182: 40 | BC182: 44 | BD182: 84 | BE182: 29 | BF182: 75
A183: 41016390 | B183: RAJDHANI FUELS | C183: ECZ_Raipur_Nava_Raipur_Sector2 | D183: RAIPUR | E183: Raipur-II SA | F183: HPC | G183: 21.171765 | H183: 81.816139 | I183: 80 | J183: 80 | K183: 84 | L183: 94 | M183: 65 | N183: 95 | O183: 78 | P183: 78 | Q183: 74 | R183: 50 | S183: 78 | T183: 50 | U183: 69 | V183: 63 | W183: 58 | X183: 64 | Y183: 68 | Z183: 74 | AA183: 75 | AB183: 65 | AC183: 64 | AD183: 54 | AE183: 70.5 | AF183: 43.5 | AG183: 74 | AH183: 62 | AI183: 75.5 | AJ183: 67.5 | AK183: 79 | AL183: 101 | AM183: 77 | AN183: 59 | AO183: 74.5 | AP183: 33.5 | AQ183: 73 | AR183: 49 | AS183: 72 | AT183: 64 | AU183: 84 | AV183: 112 | AW183: 79 | AX183: 99 | AY183: 82 | AZ183: 94 | BA183: 78 | BB183: 78 | BC183: 74 | BD183: 80 | BE183: 86 | BF183: 92
...

Sheet District Wise MKT
C1: MS-R
C2: District | D2: HPC C | E2: HPC H | F2: Gr% | G2: MKT C | H2: MKT H | I2: Gain/Loss | J2: MOP UP Vol. | K2: BPC C | L2: BPC H | M2: Gr% | N2: MKT C | O2: MKT H | P2: Gain/Loss | Q2: IOC C | R2: IOC H | S2: Gr% | T2: MKT C | U2: MKT H | V2: Gain/Loss | W2: NEL C | X2: NEL H | Y2: Gr% | Z2: MKT C | AA2: MKT H | AB2: Gain/Loss | AC2: Jio BP C | AD2: Jio BP H | AE2: Gr% | AF2: MKT C | AG2: MKT H | AH2: Gain/Loss | AI2: IND MS C | AJ2: IND MS H | AK2: Gr%
C3: Bemetara | F3: =(D3-E3)/E3% -> #DIV/0! | G3: =D3/AI3% -> #DIV/0! | H3: =E3/AJ3% -> #DIV/0! | I3: =G3-H3 -> #DIV/0! | J3: =((D3*AJ3)-(AI3*E3))/(AJ3-E3) -> #DIV/0! | M3: =(K3-L3)/L3% -> #DIV/0! | N3: =K3/AI3% -> #DIV/0! | O3: =L3/AJ3% -> #DIV/0! | P3: =N3-O3 -> #DIV/0! | S3: =(Q3-R3)/Q3% -> #DIV/0! | T3: =Q3/AI3% -> #DIV/0! | U3: =R3/AJ3% -> #DIV/0! | V3: =T3-U3 -> #DIV/0! | Y3: =(W3-X3)/W3% -> #DIV/0! | Z3: =W3/AO3% -> #DIV/0! | AA3: =X3/AP3% -> #DIV/0! | AB3: =Z3-AA3 -> #DIV/0! | AE3: =(AC3-AD3)/AC3% -> #DIV/0! | AF3: =AC3/AU3% -> #DIV/0! | AG3: =AD3/AV3% -> #DIV/0! | AH3: =AF3-AG3 -> #DIV/0! | AI3: =D3+K3+Q3+W3+AC3 -> 0 | AJ3: =E3+L3+R3+X3+AD3 -> 0 | AK3: =(AI3-AJ3)/AJ3% -> #DIV/0!
C4: Durg | F4: =(D4-E4)/E4% -> #DIV/0! | G4: =D4/AI4% -> #DIV/0! | H4: =E4/AJ4% -> #DIV/0! | I4: =G4-H4 -> #DIV/0! | J4: =((D4*AJ4)-(AI4*E4))/(AJ4-E4) -> #DIV/0! | M4: =(K4-L4)/L4% -> #DIV/0! | N4: =K4/AI4% -> #DIV/0! | O4: =L4/AJ4% -> #DIV/0! | P4: =N4-O4 -> #DIV/0! | S4: =(Q4-R4)/Q4% -> #DIV/0! | T4: =Q4/AI4% -> #DIV/0! | U4: =R4/AJ4% -> #DIV/0! | V4: =T4-U4 -> #DIV/0! | Y4: =(W4-X4)/W4% -> #DIV/0! | Z4: =W4/AO4% -> #DIV/0! | AA4: =X4/AP4% -> #DIV/0! | AB4: =Z4-AA4 -> #DIV/0! | AE4: =(AC4-AD4)/AC4% -> #DIV/0! | AF4: =AC4/AU4% -> #DIV/0! | AG4: =AD4/AV4% -> #DIV/0! | AH4: =AF4-AG4 -> #DIV/0! | AI4: =D4+K4+Q4+W4+AC4 -> 0 | AJ4: =E4+L4+R4+X4+AD4 -> 0 | AK4: =(AI4-AJ4)/AJ4% -> #DIV/0!
C5: Raipur | F5: =(D5-E5)/E5% -> #DIV/0! | G5: =D5/AI5% -> #DIV/0! | H5: =E5/AJ5% -> #DIV/0! | I5: =G5-H5 -> #DIV/0! | J5: =((D5*AJ5)-(AI5*E5))/(AJ5-E5) -> #DIV/0! | M5: =(K5-L5)/L5% -> #DIV/0! | N5: =K5/AI5% -> #DIV/0! | O5: =L5/AJ5% -> #DIV/0! | P5: =N5-O5 -> #DIV/0! | S5: =(Q5-R5)/Q5% -> #DIV/0! | T5: =Q5/AI5% -> #DIV/0! | U5: =R5/AJ5% -> #DIV/0! | V5: =T5-U5 -> #DIV/0! | Y5: =(W5-X5)/W5% -> #DIV/0! | Z5: =W5/AO5% -> #DIV/0! | AA5: =X5/AP5% -> #DIV/0! | AB5: =Z5-AA5 -> #DIV/0! | AE5: =(AC5-AD5)/AC5% -> #DIV/0! | AF5: =AC5/AU5% -> #DIV/0! | AG5: =AD5/AV5% -> #DIV/0! | AH5: =AF5-AG5 -> #DIV/0! | AI5: =D5+K5+Q5+W5+AC5 -> 0 | AJ5: =E5+L5+R5+X5+AD5 -> 0 | AK5: =(AI5-AJ5)/AJ5% -> #DIV/0!
C6: Raipur-II | F6: =(D6-E6)/E6% -> #DIV/0! | G6: =D6/AI6% -> #DIV/0! | H6: =E6/AJ6% -> #DIV/0! | I6: 0 | J6: =((D6*AJ6)-(AI6*E6))/(AJ6-E6) -> #DIV/0! | M6: =(K6-L6)/L6% -> #DIV/0! | N6: =K6/AI6% -> #DIV/0! | O6: =L6/AJ6% -> #DIV/0! | P6: =N6-O6 -> #DIV/0! | S6: =(Q6-R6)/Q6% -> #DIV/0! | T6: =Q6/AI6% -> #DIV/0! | U6: =R6/AJ6% -> #DIV/0! | V6: =T6-U6 -> #DIV/0! | Y6: =(W6-X6)/W6% -> #DIV/0! | Z6: =W6/AO6% -> #DIV/0! | AA6: =X6/AP6% -> #DIV/0! | AB6: =Z6-AA6 -> #DIV/0! | AE6: =(AC6-AD6)/AC6% -> #DIV/0! | AF6: =AC6/AU6% -> #DIV/0! | AG6: =AD6/AV6% -> #DIV/0! | AH6: =AF6-AG6 -> #DIV/0! | AI6: =D6+K6+Q6+W6+AC6 -> 0 | AJ6: =E6+L6+R6+X6+AD6 -> 0 | AK6: =(AI6-AJ6)/AJ6% -> #DIV/0!
C7: Balod | F7: =(D7-E7)/E7% -> #DIV/0! | G7: =D7/AI7% -> #DIV/0! | H7: =E7/AJ7% -> #DIV/0! | I7: =G7-H7 -> #DIV/0! | J7: =((D7*AJ7)-(AI7*E7))/(AJ7-E7) -> #DIV/0! | M7: =(K7-L7)/L7% -> #DIV/0! | N7: =K7/AI7% -> #DIV/0! | O7: =L7/AJ7% -> #DIV/0! | P7: =N7-O7 -> #DIV/0! | S7: =(Q7-R7)/Q7% -> #DIV/0! | T7: =Q7/AI7% -> #DIV/0! | U7: =R7/AJ7% -> #DIV/0! | V7: =T7-U7 -> #DIV/0! | Y7: =(W7-X7)/W7% -> #DIV/0! | Z7: =W7/AO7% -> #DIV/0! | AA7: =X7/AP7% -> #DIV/0! | AB7: =Z7-AA7 -> #DIV/0! | AE7: =(AC7-AD7)/AC7% -> #DIV/0! | AF7: =AC7/AU7% -> #DIV/0! | AG7: =AD7/AV7% -> #DIV/0! | AH7: =AF7-AG7 -> #DIV/0! | AI7: =D7+K7+Q7+W7+AC7 -> 0 | AJ7: =E7+L7+R7+X7+AD7 -> 0 | AK7: =(AI7-AJ7)/AJ7% -> #DIV/0!
C8: Dhamtari | F8: =(D8-E8)/E8% -> #DIV/0! | G8: =D8/AI8% -> #DIV/0! | H8: =E8/AJ8% -> #DIV/0! | I8: =G8-H8 -> #DIV/0! | J8: =((D8*AJ8)-(AI8*E8))/(AJ8-E8) -> #DIV/0! | M8: =(K8-L8)/L8% -> #DIV/0! | N8: =K8/AI8% -> #DIV/0! | O8: =L8/AJ8% -> #DIV/0! | P8: =N8-O8 -> #DIV/0! | S8: =(Q8-R8)/Q8% -> #DIV/0! | T8: =Q8/AI8% -> #DIV/0! | U8: =R8/AJ8% -> #DIV/0! | V8: =T8-U8 -> #DIV/0! | Y8: =(W8-X8)/W8% -> #DIV/0! | Z8: =W8/AO8% -> #DIV/0! | AA8: =X8/AP8% -> #DIV/0! | AB8: =Z8-AA8 -> #DIV/0! | AE8: =(AC8-AD8)/AC8% -> #DIV/0! | AF8: =AC8/AU8% -> #DIV/0! | AG8: =AD8/AV8% -> #DIV/0! | AH8: =AF8-AG8 -> #DIV/0! | AI8: =D8+K8+Q8+W8+AC8 -> 0 | AJ8: =E8+L8+R8+X8+AD8 -> 0 | AK8: =(AI8-AJ8)/AJ8% -> #DIV/0!
C9: Gariyaband | F9: =(D9-E9)/E9% -> #DIV/0! | G9: =D9/AI9% -> #DIV/0! | H9: =E9/AJ9% -> #DIV/0! | I9: =G9-H9 -> #DIV/0! | J9: =((D9*AJ9)-(AI9*E9))/(AJ9-E9) -> #DIV/0! | M9: =(K9-L9)/L9% -> #DIV/0! | N9: =K9/AI9% -> #DIV/0! | O9: =L9/AJ9% -> #DIV/0! | P9: =N9-O9 -> #DIV/0! | S9: =(Q9-R9)/Q9% -> #DIV/0! | T9: =Q9/AI9% -> #DIV/0! | U9: =R9/AJ9% -> #DIV/0! | V9: =T9-U9 -> #DIV/0! | Y9: =(W9-X9)/W9% -> #DIV/0! | Z9: =W9/AO9% -> #DIV/0! | AA9: =X9/AP9% -> #DIV/0! | AB9: =Z9-AA9 -> #DIV/0! | AE9: =(AC9-AD9)/AC9% -> #DIV/0! | AF9: =AC9/AU9% -> #DIV/0! | AG9: =AD9/AV9% -> #DIV/0! | AH9: =AF9-AG9 -> #DIV/0! | AI9: =D9+K9+Q9+W9+AC9 -> 0 | AJ9: =E9+L9+R9+X9+AD9 -> 0 | AK9: =(AI9-AJ9)/AJ9% -> #DIV/0!
C10: Bastar | F10: =(D10-E10)/E10% -> #DIV/0! | G10: =D10/AI10% -> #DIV/0! | H10: =E10/AJ10% -> #DIV/0! | I10: =G10-H10 -> #DIV/0! | J10: =((D10*AJ10)-(AI10*E10))/(AJ10-E10) -> #DIV/0! | M10: =(K10-L10)/L10% -> #DIV/0! | N10: =K10/AI10% -> #DIV/0! | O10: =L10/AJ10% -> #DIV/0! | P10: =N10-O10 -> #DIV/0! | S10: =(Q10-R10)/Q10% -> #DIV/0! | T10: =Q10/AI10% -> #DIV/0! | U10: =R10/AJ10% -> #DIV/0! | V10: =T10-U10 -> #DIV/0! | Y10: =(W10-X10)/W10% -> #DIV/0! | Z10: =W10/AO10% -> #DIV/0! | AA10: =X10/AP10% -> #DIV/0! | AB10: =Z10-AA10 -> #DIV/0! | AE10: =(AC10-AD10)/AC10% -> #DIV/0! | AF10: =AC10/AU10% -> #DIV/0! | AG10: =AD10/AV10% -> #DIV/0! | AH10: =AF10-AG10 -> #DIV/0! | AI10: =D10+K10+Q10+W10+AC10 -> 0 | AJ10: =E10+L10+R10+X10+AD10 -> 0 | AK10: =(AI10-AJ10)/AJ10% -> #DIV/0!
C11: Bijapur | F11: =(D11-E11)/E11% -> #DIV/0! | G11: =D11/AI11% -> #DIV/0! | H11: =E11/AJ11% -> #DIV/0! | I11: =G11-H11 -> #DIV/0! | J11: =((D11*AJ11)-(AI11*E11))/(AJ11-E11) -> #DIV/0! | M11: =(K11-L11)/L11% -> #DIV/0! | N11: =K11/AI11% -> #DIV/0! | O11: =L11/AJ11% -> #DIV/0! | P11: =N11-O11 -> #DIV/0! | S11: =(Q11-R11)/Q11% -> #DIV/0! | T11: =Q11/AI11% -> #DIV/0! | U11: =R11/AJ11% -> #DIV/0! | V11: =T11-U11 -> #DIV/0! | Y11: =(W11-X11)/W11% -> #DIV/0! | Z11: =W11/AO11% -> #DIV/0! | AA11: =X11/AP11% -> #DIV/0! | AB11: =Z11-AA11 -> #DIV/0! | AE11: =(AC11-AD11)/AC11% -> #DIV/0! | AF11: =AC11/AU11% -> #DIV/0! | AG11: =AD11/AV11% -> #DIV/0! | AH11: =AF11-AG11 -> #DIV/0! | AI11: =D11+K11+Q11+W11+AC11 -> 0 | AJ11: =E11+L11+R11+X11+AD11 -> 0 | AK11: =(AI11-AJ11)/AJ11% -> #DIV/0!
C12: Dantewada | F12: =(D12-E12)/E12% -> #DIV/0! | G12: =D12/AI12% -> #DIV/0! | H12: =E12/AJ12% -> #DIV/0! | I12: =G12-H12 -> #DIV/0! | J12: =((D12*AJ12)-(AI12*E12))/(AJ12-E12) -> #DIV/0! | M12: =(K12-L12)/L12% -> #DIV/0! | N12: =K12/AI12% -> #DIV/0! | O12: =L12/AJ12% -> #DIV/0! | P12: =N12-O12 -> #DIV/0! | S12: =(Q12-R12)/Q12% -> #DIV/0! | T12: =Q12/AI12% -> #DIV/0! | U12: =R12/AJ12% -> #DIV/0! | V12: =T12-U12 -> #DIV/0! | Y12: =(W12-X12)/W12% -> #DIV/0! | Z12: =W12/AO12% -> #DIV/0! | AA12: =X12/AP12% -> #DIV/0! | AB12: =Z12-AA12 -> #DIV/0! | AE12: =(AC12-AD12)/AC12% -> #DIV/0! | AF12: =AC12/AU12% -> #DIV/0! | AG12: =AD12/AV12% -> #DIV/0! | AH12: =AF12-AG12 -> #DIV/0! | AI12: =D12+K12+Q12+W12+AC12 -> 0 | AJ12: =E12+L12+R12+X12+AD12 -> 0 | AK12: =(AI12-AJ12)/AJ12% -> #DIV/0!
C13: Kanker | F13: =(D13-E13)/E13% -> #DIV/0! | G13: =D13/AI13% -> #DIV/0! | H13: =E13/AJ13% -> #DIV/0! | I13: =G13-H13 -> #DIV/0! | J13: =((D13*AJ13)-(AI13*E13))/(AJ13-E13) -> #DIV/0! | M13: =(K13-L13)/L13% -> #DIV/0! | N13: =K13/AI13% -> #DIV/0! | O13: =L13/AJ13% -> #DIV/0! | P13: =N13-O13 -> #DIV/0! | S13: =(Q13-R13)/Q13% -> #DIV/0! | T13: =Q13/AI13% -> #DIV/0! | U13: =R13/AJ13% -> #DIV/0! | V13: =T13-U13 -> #DIV/0! | Y13: =(W13-X13)/W13% -> #DIV/0! | Z13: =W13/AO13% -> #DIV/0! | AA13: =X13/AP13% -> #DIV/0! | AB13: =Z13-AA13 -> #DIV/0! | AE13: =(AC13-AD13)/AC13% -> #DIV/0! | AF13: =AC13/AU13% -> #DIV/0! | AG13: =AD13/AV13% -> #DIV/0! | AH13: =AF13-AG13 -> #DIV/0! | AI13: =D13+K13+Q13+W13+AC13 -> 0 | AJ13: =E13+L13+R13+X13+AD13 -> 0 | AK13: =(AI13-AJ13)/AJ13% -> #DIV/0!
C14: Kondagaon | F14: =(D14-E14)/E14% -> #DIV/0! | G14: =D14/AI14% -> #DIV/0! | H14: =E14/AJ14% -> #DIV/0! | I14: =G14-H14 -> #DIV/0! | J14: =((D14*AJ14)-(AI14*E14))/(AJ14-E14) -> #DIV/0! | M14: =(K14-L14)/L14% -> #DIV/0! | N14: =K14/AI14% -> #DIV/0! | O14: =L14/AJ14% -> #DIV/0! | P14: =N14-O14 -> #DIV/0! | S14: =(Q14-R14)/Q14% -> #DIV/0! | T14: =Q14/AI14% -> #DIV/0! | U14: =R14/AJ14% -> #DIV/0! | V14: =T14-U14 -> #DIV/0! | Y14: =(W14-X14)/W14% -> #DIV/0! | Z14: =W14/AO14% -> #DIV/0! | AA14: =X14/AP14% -> #DIV/0! | AB14: =Z14-AA14 -> #DIV/0! | AE14: =(AC14-AD14)/AC14% -> #DIV/0! | AF14: =AC14/AU14% -> #DIV/0! | AG14: =AD14/AV14% -> #DIV/0! | AH14: =AF14-AG14 -> #DIV/0! | AI14: =D14+K14+Q14+W14+AC14 -> 0 | AJ14: =E14+L14+R14+X14+AD14 -> 0 | AK14: =(AI14-AJ14)/AJ14% -> #DIV/0!
C15: NARAINPUR | F15: =(D15-E15)/E15% -> #DIV/0! | G15: =D15/AI15% -> #DIV/0! | H15: =E15/AJ15% -> #DIV/0! | I15: =G15-H15 -> #DIV/0! | J15: =((D15*AJ15)-(AI15*E15))/(AJ15-E15) -> #DIV/0! | M15: =(K15-L15)/L15% -> #DIV/0! | N15: =K15/AI15% -> #DIV/0! | O15: =L15/AJ15% -> #DIV/0! | P15: =N15-O15 -> #DIV/0! | S15: =(Q15-R15)/Q15% -> #DIV/0! | T15: =Q15/AI15% -> #DIV/0! | U15: =R15/AJ15% -> #DIV/0! | V15: =T15-U15 -> #DIV/0! | Y15: =(W15-X15)/W15% -> #DIV/0! | Z15: =W15/AO15% -> #DIV/0! | AA15: =X15/AP15% -> #DIV/0! | AB15: =Z15-AA15 -> #DIV/0! | AE15: =(AC15-AD15)/AC15% -> #DIV/0! | AF15: =AC15/AU15% -> #DIV/0! | AG15: =AD15/AV15% -> #DIV/0! | AH15: =AF15-AG15 -> #DIV/0! | AI15: =D15+K15+Q15+W15+AC15 -> 0 | AJ15: =E15+L15+R15+X15+AD15 -> 0 | AK15: =(AI15-AJ15)/AJ15% -> #DIV/0!
C16: Sukma | F16: =(D16-E16)/E16% -> #DIV/0! | G16: =D16/AI16% -> #DIV/0! | H16: =E16/AJ16% -> #DIV/0! | I16: =G16-H16 -> #DIV/0! | J16: =((D16*AJ16)-(AI16*E16))/(AJ16-E16) -> #DIV/0! | M16: =(K16-L16)/L16% -> #DIV/0! | N16: =K16/AI16% -> #DIV/0! | O16: =L16/AJ16% -> #DIV/0! | P16: =N16-O16 -> #DIV/0! | S16: =(Q16-R16)/Q16% -> #DIV/0! | T16: =Q16/AI16% -> #DIV/0! | U16: =R16/AJ16% -> #DIV/0! | V16: =T16-U16 -> #DIV/0! | Y16: =(W16-X16)/W16% -> #DIV/0! | Z16: =W16/AO16% -> #DIV/0! | AA16: =X16/AP16% -> #DIV/0! | AB16: =Z16-AA16 -> #DIV/0! | AE16: =(AC16-AD16)/AC16% -> #DIV/0! | AF16: =AC16/AU16% -> #DIV/0! | AG16: =AD16/AV16% -> #DIV/0! | AH16: =AF16-AG16 -> #DIV/0! | AI16: =D16+K16+Q16+W16+AC16 -> 0 | AJ16: =E16+L16+R16+X16+AD16 -> 0 | AK16: =(AI16-AJ16)/AJ16% -> #DIV/0!
C17: Kawardha | F17: =(D17-E17)/E17% -> #DIV/0! | G17: =D17/AI17% -> #DIV/0! | H17: =E17/AJ17% -> #DIV/0! | I17: =G17-H17 -> #DIV/0! | J17: =((D17*AJ17)-(AI17*E17))/(AJ17-E17) -> #DIV/0! | M17: =(K17-L17)/L17% -> #DIV/0! | N17: =K17/AI17% -> #DIV/0! | O17: =L17/AJ17% -> #DIV/0! | P17: =N17-O17 -> #DIV/0! | S17: =(Q17-R17)/Q17% -> #DIV/0! | T17: =Q17/AI17% -> #DIV/0! | U17: =R17/AJ17% -> #DIV/0! | V17: =T17-U17 -> #DIV/0! | Y17: =(W17-X17)/W17% -> #DIV/0! | Z17: =W17/AO17% -> #DIV/0! | AA17: =X17/AP17% -> #DIV/0! | AB17: =Z17-AA17 -> #DIV/0! | AE17: =(AC17-AD17)/AC17% -> #DIV/0! | AF17: =AC17/AU17% -> #DIV/0! | AG17: =AD17/AV17% -> #DIV/0! | AH17: =AF17-AG17 -> #DIV/0! | AI17: =D17+K17+Q17+W17+AC17 -> 0 | AJ17: =E17+L17+R17+X17+AD17 -> 0 | AK17: =(AI17-AJ17)/AJ17% -> #DIV/0!
C18: Khairgarh Chhuikhadan Gandai | F18: =(D18-E18)/E18% -> #DIV/0! | G18: =D18/AI18% -> #DIV/0! | H18: =E18/AJ18% -> #DIV/0! | I18: =G18-H18 -> #DIV/0! | J18: =((D18*AJ18)-(AI18*E18))/(AJ18-E18) -> #DIV/0! | M18: =(K18-L18)/L18% -> #DIV/0! | N18: =K18/AI18% -> #DIV/0! | O18: =L18/AJ18% -> #DIV/0! | P18: =N18-O18 -> #DIV/0! | S18: =(Q18-R18)/Q18% -> #DIV/0! | T18: =Q18/AI18% -> #DIV/0! | U18: =R18/AJ18% -> #DIV/0! | V18: =T18-U18 -> #DIV/0! | Y18: =(W18-X18)/W18% -> #DIV/0! | Z18: =W18/AO18% -> #DIV/0! | AA18: =X18/AP18% -> #DIV/0! | AB18: =Z18-AA18 -> #DIV/0! | AE18: =(AC18-AD18)/AC18% -> #DIV/0! | AF18: =AC18/AU18% -> #DIV/0! | AG18: =AD18/AV18% -> #DIV/0! | AH18: =AF18-AG18 -> #DIV/0! | AI18: =D18+K18+Q18+W18+AC18 -> 0 | AJ18: =E18+L18+R18+X18+AD18 -> 0 | AK18: =(AI18-AJ18)/AJ18% -> #DIV/0!
... C20: Rajnandgaon | F20: =(D20-E20)/E20% -> #DIV/0! | G20: =D20/AI20% -> #DIV/0! | H20: =E20/AJ20% -> #DIV/0! | I20: =G20-H20 -> #DIV/0! | J20: =((D20*AJ20)-(AI20*E20))/(AJ20-E20) -> #DIV/0! | M20: =(K20-L20)/L20% -> #DIV/0! | N20: =K20/AI20% -> #DIV/0! | O20: =L20/AJ20% -> #DIV/0! | P20: =N20-O20 -> #DIV/0! | S20: =(Q20-R20)/Q20% -> #DIV/0! | T20: =Q20/AI20% -> #DIV/0! | U20: =R20/AJ20% -> #DIV/0! | V20: =T20-U20 -> #DIV/0! | Y20: =(W20-X20)/W20% -> #DIV/0! | Z20: =W20/AO20% -> #DIV/0! | AA20: =X20/AP20% -> #DIV/0! | AB20: =Z20-AA20 -> #DIV/0! | AE20: =(AC20-AD20)/AC20% -> #DIV/0! | AF20: =AC20/AU20% -> #DIV/0! | AG20: =AD20/AV20% -> #DIV/0! | AH20: =AF20-AG20 -> #DIV/0! | AI20: =D20+K20+Q20+W20+AC20 -> 0 | AJ20: =E20+L20+R20+X20+AD20 -> 0 | AK20: =(AI20-AJ20)/AJ20% -> #DIV/0!
C21: Raipur Region | D21: =SUM(D3:D20) -> 0 | E21: =SUM(E3:E20) -> 0 | F21: =(D21-E21)/E21% -> #DIV/0! | G21: =D21/AI21% -> #DIV/0! | H21: =E21/AJ21% -> #DIV/0! | I21: =G21-H21 -> #DIV/0! | J21: =((D21*AJ21)-(AI21*E21))/(AJ21-E21) -> #DIV/0! | K21: =SUM(K3:K20) -> 0 | L21: =SUM(L3:L20) -> 0 | M21: =(K21-L21)/L21% -> #DIV/0! | N21: =K21/AI21% -> #DIV/0! | O21: =L21/AJ21% -> #DIV/0! | P21: =N21-O21 -> #DIV/0! | Q21: =SUM(Q3:Q20) -> 0 | R21: =SUM(R3:R20) -> 0 | S21: =(Q21-R21)/Q21% -> #DIV/0! | T21: =Q21/AI21% -> #DIV/0! | U21: =R21/AJ21% -> #DIV/0! | V21: =T21-U21 -> #DIV/0! | Y21: =(W21-X21)/W21% -> #DIV/0! | Z21: =W21/AO21% -> #DIV/0! | AA21: =X21/AP21% -> #DIV/0! | AB21: =Z21-AA21 -> #DIV/0! | AE21: =(AC21-AD21)/AC21% -> #DIV/0! | AF21: =AC21/AU21% -> #DIV/0! | AG21: =AD21/AV21% -> #DIV/0! | AH21: =AF21-AG21 -> #DIV/0! | AI21: =D21+K21+Q21 -> 0 | AJ21: =E21+L21+R21 -> 0 | AK21: =(AI21-AJ21)/AJ21% -> #DIV/0!
C22: HSD-R
C23: District | D23: HPC C | E23: HPC H | F23: Gr% | G23: MKT C | H23: MKT H | I23: Gain/Loss | J23: MOP UP Vol. | K23: BPC C | L23: BPC H | M23: Gr% | N23: MKT C | O23: MKT H | P23: Gain/Loss | Q23: IOC C | R23: IOC H | S23: Gr% | T23: MKT C | U23: MKT H | V23: Gain/Loss | W23: NEL C | X23: NEL H | Y23: Gr% | Z23: MKT C | AA23: MKT H | AB23: Gain/Loss | AC23: Jio BP C | AD23: Jio BP H | AE23: Gr% | AF23: MKT C | AG23: MKT H | AH23: Gain/Loss | AI23: IND MS C | AJ23: IND MS H | AK23: Gr%
C24: Bemetara | F24: =(D24-E24)/E24% -> #DIV/0! | G24: =D24/AI24% -> #DIV/0! | H24: =E24/AJ24% -> #DIV/0! | I24: =G24-H24 -> #DIV/0! | J24: =((D24*AJ24)-(AI24*E24))/(AJ24-E24) -> #DIV/0! | M24: =(K24-L24)/L24% -> #DIV/0! | N24: =K24/AI24% -> #DIV/0! | O24: =L24/AJ24% -> #DIV/0! | P24: =N24-O24 -> #DIV/0! | S24: =(Q24-R24)/Q24% -> #DIV/0! | T24: =Q24/AI24% -> #DIV/0! | U24: =R24/AJ24% -> #DIV/0! | V24: =T24-U24 -> #DIV/0! | Y24: =(W24-X24)/W24% -> #DIV/0! | Z24: =W24/AO24% -> #DIV/0! | AA24: =X24/AP24% -> #DIV/0! | AB24: =Z24-AA24 -> #DIV/0! | AE24: =(AC24-AD24)/AC24% -> #DIV/0! | AF24: =AC24/AU24% -> #DIV/0! | AG24: =AD24/AV24% -> #DIV/0! | AH24: =AF24-AG24 -> #DIV/0! | AI24: =D24+K24+Q24+W24+AC24 -> 0 | AJ24: =E24+L24+R24+X24+AD24 -> 0 | AK24: =(AI24-AJ24)/AJ24% -> #DIV/0!
C25: Durg | F25: =(D25-E25)/E25% -> #DIV/0! | G25: =D25/AI25% -> #DIV/0! | H25: =E25/AJ25% -> #DIV/0! | I25: =G25-H25 -> #DIV/0! | J25: =((D25*AJ25)-(AI25*E25))/(AJ25-E25) -> #DIV/0! | M25: =(K25-L25)/L25% -> #DIV/0! | N25: =K25/AI25% -> #DIV/0! | O25: =L25/AJ25% -> #DIV/0! | P25: =N25-O25 -> #DIV/0! | S25: =(Q25-R25)/Q25% -> #DIV/0! | T25: =Q25/AI25% -> #DIV/0! | U25: =R25/AJ25% -> #DIV/0! | V25: =T25-U25 -> #DIV/0! | Y25: =(W25-X25)/W25% -> #DIV/0! | Z25: =W25/AO25% -> #DIV/0! | AA25: =X25/AP25% -> #DIV/0! | AB25: =Z25-AA25 -> #DIV/0! | AE25: =(AC25-AD25)/AC25% -> #DIV/0! | AF25: =AC25/AU25% -> #DIV/0! | AG25: =AD25/AV25% -> #DIV/0! | AH25: =AF25-AG25 -> #DIV/0! | AI25: =D25+K25+Q25+W25+AC25 -> 0 | AJ25: =E25+L25+R25+X25+AD25 -> 0 | AK25: =(AI25-AJ25)/AJ25% -> #DIV/0!
C26: Raipur | F26: =(D26-E26)/E26% -> #DIV/0! | G26: =D26/AI26% -> #DIV/0! | H26: =E26/AJ26% -> #DIV/0! | I26: =G26-H26 -> #DIV/0! | J26: =((D26*AJ26)-(AI26*E26))/(AJ26-E26) -> #DIV/0! | M26: =(K26-L26)/L26% -> #DIV/0! | N26: =K26/AI26% -> #DIV/0! | O26: =L26/AJ26% -> #DIV/0! | P26: =N26-O26 -> #DIV/0! | S26: =(Q26-R26)/Q26% -> #DIV/0! | T26: =Q26/AI26% -> #DIV/0! | U26: =R26/AJ26% -> #DIV/0! | V26: =T26-U26 -> #DIV/0! | Y26: =(W26-X26)/W26% -> #DIV/0! | Z26: =W26/AO26% -> #DIV/0! | AA26: =X26/AP26% -> #DIV/0! | AB26: =Z26-AA26 -> #DIV/0! | AE26: =(AC26-AD26)/AC26% -> #DIV/0! | AF26: =AC26/AU26% -> #DIV/0! | AG26: =AD26/AV26% -> #DIV/0! | AH26: =AF26-AG26 -> #DIV/0! | AI26: =D26+K26+Q26+W26+AC26 -> 0 | AJ26: =E26+L26+R26+X26+AD26 -> 0 | AK26: =(AI26-AJ26)/AJ26% -> #DIV/0!
C27: Raipur-II | F27: =(D27-E27)/E27% -> #DIV/0! | G27: =D27/AI27% -> #DIV/0! | H27: =E27/AJ27% -> #DIV/0! | I27: =G27-H27 -> #DIV/0! | J27: =((D27*AJ27)-(AI27*E27))/(AJ27-E27) -> #DIV/0! | M27: =(K27-L27)/L27% -> #DIV/0! | N27: =K27/AI27% -> #DIV/0! | O27: =L27/AJ27% -> #DIV/0! | P27: =N27-O27 -> #DIV/0! | S27: =(Q27-R27)/Q27% -> #DIV/0! | T27: =Q27/AI27% -> #DIV/0! | U27: =R27/AJ27% -> #DIV/0! | V27: =T27-U27 -> #DIV/0! | Y27: =(W27-X27)/W27% -> #DIV/0! | Z27: =W27/AO27% -> #DIV/0! | AA27: =X27/AP27% -> #DIV/0! | AB27: =Z27-AA27 -> #DIV/0! | AE27: =(AC27-AD27)/AC27% -> #DIV/0! | AF27: =AC27/AU27% -> #DIV/0! | AG27: =AD27/AV27% -> #DIV/0! | AH27: =AF27-AG27 -> #DIV/0! | AI27: =D27+K27+Q27+W27+AC27 -> 0 | AJ27: =E27+L27+R27+X27+AD27 -> 0 | AK27: =(AI27-AJ27)/AJ27% -> #DIV/0!
C28: Balod | F28: =(D28-E28)/E28% -> #DIV/0! | G28: =D28/AI28% -> #DIV/0! | H28: =E28/AJ28% -> #DIV/0! | I28: =G28-H28 -> #DIV/0! | J28: =((D28*AJ28)-(AI28*E28))/(AJ28-E28) -> #DIV/0! | M28: =(K28-L28)/L28% -> #DIV/0! | N28: =K28/AI28% -> #DIV/0! | O28: =L28/AJ28% -> #DIV/0! | P28: =N28-O28 -> #DIV/0! | S28: =(Q28-R28)/Q28% -> #DIV/0! | T28: =Q28/AI28% -> #DIV/0! | U28: =R28/AJ28% -> #DIV/0! | V28: =T28-U28 -> #DIV/0! | Y28: =(W28-X28)/W28% -> #DIV/0! | Z28: =W28/AO28% -> #DIV/0! | AA28: =X28/AP28% -> #DIV/0! | AB28: =Z28-AA28 -> #DIV/0! | AE28: =(AC28-AD28)/AC28% -> #DIV/0! | AF28: =AC28/AU28% -> #DIV/0! | AG28: =AD28/AV28% -> #DIV/0! | AH28: =AF28-AG28 -> #DIV/0! | AI28: =D28+K28+Q28+W28+AC28 -> 0 | AJ28: =E28+L28+R28+X28+AD28 -> 0 | AK28: =(AI28-AJ28)/AJ28% -> #DIV/0!
C29: Dhamtari | F29: =(D29-E29)/E29% -> #DIV/0! | G29: =D29/AI29% -> #DIV/0! | H29: =E29/AJ29% -> #DIV/0! | I29: =G29-H29 -> #DIV/0! | J29: =((D29*AJ29)-(AI29*E29))/(AJ29-E29) -> #DIV/0! | M29: =(K29-L29)/L29% -> #DIV/0! | N29: =K29/AI29% -> #DIV/0! | O29: =L29/AJ29% -> #DIV/0! | P29: =N29-O29 -> #DIV/0! | S29: =(Q29-R29)/Q29% -> #DIV/0! | T29: =Q29/AI29% -> #DIV/0! | U29: =R29/AJ29% -> #DIV/0! | V29: =T29-U29 -> #DIV/0! | Y29: =(W29-X29)/W29% -> #DIV/0! | Z29: =W29/AO29% -> #DIV/0! | AA29: =X29/AP29% -> #DIV/0! | AB29: =Z29-AA29 -> #DIV/0! | AE29: =(AC29-AD29)/AC29% -> #DIV/0! | AF29: =AC29/AU29% -> #DIV/0! | AG29: =AD29/AV29% -> #DIV/0! | AH29: =AF29-AG29 -> #DIV/0! | AI29: =D29+K29+Q29+W29+AC29 -> 0 | AJ29: =E29+L29+R29+X29+AD29 -> 0 | AK29: =(AI29-AJ29)/AJ29% -> #DIV/0!
C30: Gariyaband | F30: =(D30-E30)/E30% -> #DIV/0! | G30: =D30/AI30% -> #DIV/0! | H30: =E30/AJ30% -> #DIV/0! | I30: =G30-H30 -> #DIV/0! | J30: =((D30*AJ30)-(AI30*E30))/(AJ30-E30) -> #DIV/0! | M30: =(K30-L30)/L30% -> #DIV/0! | N30: =K30/AI30% -> #DIV/0! | O30: =L30/AJ30% -> #DIV/0! | P30: =N30-O30 -> #DIV/0! | S30: =(Q30-R30)/Q30% -> #DIV/0! | T30: =Q30/AI30% -> #DIV/0! | U30: =R30/AJ30% -> #DIV/0! | V30: =T30-U30 -> #DIV/0! | Y30: =(W30-X30)/W30% -> #DIV/0! | Z30: =W30/AO30% -> #DIV/0! | AA30: =X30/AP30% -> #DIV/0! | AB30: =Z30-AA30 -> #DIV/0! | AE30: =(AC30-AD30)/AC30% -> #DIV/0! | AF30: =AC30/AU30% -> #DIV/0! | AG30: =AD30/AV30% -> #DIV/0! | AH30: =AF30-AG30 -> #DIV/0! | AI30: =D30+K30+Q30+W30+AC30 -> 0 | AJ30: =E30+L30+R30+X30+AD30 -> 0 | AK30: =(AI30-AJ30)/AJ30% -> #DIV/0!
C31: Bastar | F31: =(D31-E31)/E31% -> #DIV/0! | G31: =D31/AI31% -> #DIV/0! | H31: =E31/AJ31% -> #DIV/0! | I31: =G31-H31 -> #DIV/0! | J31: =((D31*AJ31)-(AI31*E31))/(AJ31-E31) -> #DIV/0! | M31: =(K31-L31)/L31% -> #DIV/0! | N31: =K31/AI31% -> #DIV/0! | O31: =L31/AJ31% -> #DIV/0! | P31: =N31-O31 -> #DIV/0! | S31: =(Q31-R31)/Q31% -> #DIV/0! | T31: =Q31/AI31% -> #DIV/0! | U31: =R31/AJ31% -> #DIV/0! | V31: =T31-U31 -> #DIV/0! | Y31: =(W31-X31)/W31% -> #DIV/0! | Z31: =W31/AO31% -> #DIV/0! | AA31: =X31/AP31% -> #DIV/0! | AB31: =Z31-AA31 -> #DIV/0! | AE31: =(AC31-AD31)/AC31% -> #DIV/0! | AF31: =AC31/AU31% -> #DIV/0! | AG31: =AD31/AV31% -> #DIV/0! | AH31: =AF31-AG31 -> #DIV/0! | AI31: =D31+K31+Q31+W31+AC31 -> 0 | AJ31: =E31+L31+R31+X31+AD31 -> 0 | AK31: =(AI31-AJ31)/AJ31% -> #DIV/0!
C32: Bijapur | F32: =(D32-E32)/E32% -> #DIV/0! | G32: =D32/AI32% -> #DIV/0! | H32: =E32/AJ32% -> #DIV/0! | I32: =G32-H32 -> #DIV/0! | J32: =((D32*AJ32)-(AI32*E32))/(AJ32-E32) -> #DIV/0! | M32: =(K32-L32)/L32% -> #DIV/0! | N32: =K32/AI32% -> #DIV/0! | O32: =L32/AJ32% -> #DIV/0! | P32: =N32-O32 -> #DIV/0! | S32: =(Q32-R32)/Q32% -> #DIV/0! | T32: =Q32/AI32% -> #DIV/0! | U32: =R32/AJ32% -> #DIV/0! | V32: =T32-U32 -> #DIV/0! | Y32: =(W32-X32)/W32% -> #DIV/0! | Z32: =W32/AO32% -> #DIV/0! | AA32: =X32/AP32% -> #DIV/0! | AB32: =Z32-AA32 -> #DIV/0! | AE32: =(AC32-AD32)/AC32% -> #DIV/0! | AF32: =AC32/AU32% -> #DIV/0! | AG32: =AD32/AV32% -> #DIV/0! | AH32: =AF32-AG32 -> #DIV/0! | AI32: =D32+K32+Q32+W32+AC32 -> 0 | AJ32: =E32+L32+R32+X32+AD32 -> 0 | AK32: =(AI32-AJ32)/AJ32% -> #DIV/0!
C33: Dantewada | F33: =(D33-E33)/E33% -> #DIV/0! | G33: =D33/AI33% -> #DIV/0! | H33: =E33/AJ33% -> #DIV/0! | I33: =G33-H33 -> #DIV/0! | J33: =((D33*AJ33)-(AI33*E33))/(AJ33-E33) -> #DIV/0! | M33: =(K33-L33)/L33% -> #DIV/0! | N33: =K33/AI33% -> #DIV/0! | O33: =L33/AJ33% -> #DIV/0! | P33: =N33-O33 -> #DIV/0! | S33: =(Q33-R33)/Q33% -> #DIV/0! | T33: =Q33/AI33% -> #DIV/0! | U33: =R33/AJ33% -> #DIV/0! | V33: =T33-U33 -> #DIV/0! | Y33: =(W33-X33)/W33% -> #DIV/0! | Z33: =W33/AO33% -> #DIV/0! | AA33: =X33/AP33% -> #DIV/0! | AB33: =Z33-AA33 -> #DIV/0! | AE33: =(AC33-AD33)/AC33% -> #DIV/0! | AF33: =AC33/AU33% -> #DIV/0! | AG33: =AD33/AV33% -> #DIV/0! | AH33: =AF33-AG33 -> #DIV/0! | AI33: =D33+K33+Q33+W33+AC33 -> 0 | AJ33: =E33+L33+R33+X33+AD33 -> 0 | AK33: =(AI33-AJ33)/AJ33% -> #DIV/0!
C34: Kanker | F34: =(D34-E34)/E34% -> #DIV/0! | G34: =D34/AI34% -> #DIV/0! | H34: =E34/AJ34% -> #DIV/0! | I34: =G34-H34 -> #DIV/0! | J34: =((D34*AJ34)-(AI34*E34))/(AJ34-E34) -> #DIV/0! | M34: =(K34-L34)/L34% -> #DIV/0! | N34: =K34/AI34% -> #DIV/0! | O34: =L34/AJ34% -> #DIV/0! | P34: =N34-O34 -> #DIV/0! | S34: =(Q34-R34)/Q34% -> #DIV/0! | T34: =Q34/AI34% -> #DIV/0! | U34: =R34/AJ34% -> #DIV/0! | V34: =T34-U34 -> #DIV/0! | Y34: =(W34-X34)/W34% -> #DIV/0! | Z34: =W34/AO34% -> #DIV/0! | AA34: =X34/AP34% -> #DIV/0! | AB34: =Z34-AA34 -> #DIV/0! | AE34: =(AC34-AD34)/AC34% -> #DIV/0! | AF34: =AC34/AU34% -> #DIV/0! | AG34: =AD34/AV34% -> #DIV/0! | AH34: =AF34-AG34 -> #DIV/0! | AI34: =D34+K34+Q34+W34+AC34 -> 0 | AJ34: =E34+L34+R34+X34+AD34 -> 0 | AK34: =(AI34-AJ34)/AJ34% -> #DIV/0!
C35: Kondagaon | F35: =(D35-E35)/E35% -> #DIV/0! | G35: =D35/AI35% -> #DIV/0! | H35: =E35/AJ35% -> #DIV/0! | I35: =G35-H35 -> #DIV/0! | J35: =((D35*AJ35)-(AI35*E35))/(AJ35-E35) -> #DIV/0! | M35: =(K35-L35)/L35% -> #DIV/0! | N35: =K35/AI35% -> #DIV/0! | O35: =L35/AJ35% -> #DIV/0! | P35: =N35-O35 -> #DIV/0! | S35: =(Q35-R35)/Q35% -> #DIV/0! | T35: =Q35/AI35% -> #DIV/0! | U35: =R35/AJ35% -> #DIV/0! | V35: =T35-U35 -> #DIV/0! | Y35: =(W35-X35)/W35% -> #DIV/0! | Z35: =W35/AO35% -> #DIV/0! | AA35: =X35/AP35% -> #DIV/0! | AB35: =Z35-AA35 -> #DIV/0! | AE35: =(AC35-AD35)/AC35% -> #DIV/0! | AF35: =AC35/AU35% -> #DIV/0! | AG35: =AD35/AV35% -> #DIV/0! | AH35: =AF35-AG35 -> #DIV/0! | AI35: =D35+K35+Q35+W35+AC35 -> 0 | AJ35: =E35+L35+R35+X35+AD35 -> 0 | AK35: =(AI35-AJ35)/AJ35% -> #DIV/0!
... C41: Rajnandgaon | F41: =(D41-E41)/E41% -> #DIV/0! | G41: =D41/AI41% -> #DIV/0! | H41: =E41/AJ41% -> #DIV/0! | I41: =G41-H41 -> #DIV/0! | J41: =((D41*AJ41)-(AI41*E41))/(AJ41-E41) -> #DIV/0! | M41: =(K41-L41)/L41% -> #DIV/0! | N41: =K41/AI41% -> #DIV/0! | O41: =L41/AJ41% -> #DIV/0! | P41: =N41-O41 -> #DIV/0! | S41: =(Q41-R41)/Q41% -> #DIV/0! | T41: =Q41/AI41% -> #DIV/0! | U41: =R41/AJ41% -> #DIV/0! | V41: =T41-U41 -> #DIV/0! | Y41: =(W41-X41)/W41% -> #DIV/0! | Z41: =W41/AO41% -> #DIV/0! | AA41: =X41/AP41% -> #DIV/0! | AB41: =Z41-AA41 -> #DIV/0! | AE41: =(AC41-AD41)/AC41% -> #DIV/0! | AF41: =AC41/AU41% -> #DIV/0! | AG41: =AD41/AV41% -> #DIV/0! | AH41: =AF41-AG41 -> #DIV/0! | AI41: =D41+K41+Q41+W41+AC41 -> 0 | AJ41: =E41+L41+R41+X41+AD41 -> 0 | AK41: =(AI41-AJ41)/AJ41% -> #DIV/0!
C42: Raipur Region | D42: =SUM(D24:D41) -> 0 | E42: =SUM(E24:E41) -> 0 | F42: =(D42-E42)/E42% -> #DIV/0! | G42: =D42/AI42% -> #DIV/0! | H42: =E42/AJ42% -> #DIV/0! | I42: =G42-H42 -> #DIV/0! | J42: =((D42*AJ42)-(AI42*E42))/(AJ42-E42) -> #DIV/0! | K42: =SUM(K24:K41) -> 0 | L42: =SUM(L24:L41) -> 0 | M42: =(K42-L42)/L42% -> #DIV/0! | N42: =K42/AI42% -> #DIV/0! | O42: =L42/AJ42% -> #DIV/0! | P42: =N42-O42 -> #DIV/0! | Q42: =SUM(Q24:Q41) -> 0 | R42: =SUM(R24:R41) -> 0 | S42: =(Q42-R42)/Q42% -> #DIV/0! | T42: =Q42/AI42% -> #DIV/0! | U42: =R42/AJ42% -> #DIV/0! | V42: =T42-U42 -> #DIV/0! | AI42: =D42+K42+Q42 -> 0 | AJ42: =E42+L42+R42 -> 0 | AK42: =(AI42-AJ42)/AJ42% -> #DIV/0!
C44: District | D44: HPC C | E44: HPC H | F44: Gr% | G44: MKT C | H44: MKT H | I44: Gain/Loss | J44: MOP UP Vol. | K44: BPC C | L44: BPC H | M44: Gr% | N44: MKT C | O44: MKT H | P44: Gain/Loss | Q44: IOC C | R44: IOC H | S44: Gr% | T44: MKT C | U44: MKT H | V44: Gain/Loss | W44: NEL C | X44: NEL H | Y44: Gr% | Z44: MKT C | AA44: MKT H | AB44: Gain/Loss | AC44: Jio BP C | AD44: Jio BP H | AE44: Gr% | AF44: MKT C | AG44: MKT H | AH44: Gain/Loss | AI44: IND MS C | AJ44: IND MS H | AK44: Gr%
C45: Bemetara | D45: =D3+D24 -> 0 | E45: =E3+E24 -> 0 | F45: =(D45-E45)/E45% -> #DIV/0! | G45: =D45/AI45% -> #DIV/0! | H45: =E45/AJ45% -> #DIV/0! | I45: =G45-H45 -> #DIV/0! | J45: =((D45*AJ45)-(AI45*E45))/(AJ45-E45) -> #DIV/0! | K45: =K3+K24 -> 0 | L45: =L3+L24 -> 0 | M45: =(K45-L45)/L45% -> #DIV/0! | N45: =K45/AI45% -> #DIV/0! | O45: =L45/AJ45% -> #DIV/0! | P45: =N45-O45 -> #DIV/0! | Q45: =Q3+Q24 -> 0 | R45: =R3+R24 -> 0 | S45: =(Q45-R45)/Q45% -> #DIV/0! | T45: =Q45/AI45% -> #DIV/0! | U45: =R45/AJ45% -> #DIV/0! | V45: =T45-U45 -> #DIV/0! | Y45: =(W45-X45)/W45% -> #DIV/0! | Z45: =W45/AO45% -> #DIV/0! | AA45: =X45/AP45% -> #DIV/0! | AB45: =Z45-AA45 -> #DIV/0! | AE45: =(AC45-AD45)/AC45% -> #DIV/0! | AF45: =AC45/AU45% -> #DIV/0! | AG45: =AD45/AV45% -> #DIV/0! | AH45: =AF45-AG45 -> #DIV/0! | AI45: =D45+K45+Q45+W45+AC45 -> 0 | AJ45: =E45+L45+R45+X45+AD45 -> 0 | AK45: =(AI45-AJ45)/AJ45% -> #DIV/0!
C46: Durg | D46: =D4+D25 -> 0 | E46: =E4+E25 -> 0 | F46: =(D46-E46)/E46% -> #DIV/0! | G46: =D46/AI46% -> #DIV/0! | H46: =E46/AJ46% -> #DIV/0! | I46: =G46-H46 -> #DIV/0! | J46: =((D46*AJ46)-(AI46*E46))/(AJ46-E46) -> #DIV/0! | K46: =K4+K25 -> 0 | L46: =L4+L25 -> 0 | M46: =(K46-L46)/L46% -> #DIV/0! | N46: =K46/AI46% -> #DIV/0! | O46: =L46/AJ46% -> #DIV/0! | P46: =N46-O46 -> #DIV/0! | Q46: =Q4+Q25 -> 0 | R46: =R4+R25 -> 0 | S46: =(Q46-R46)/Q46% -> #DIV/0! | T46: =Q46/AI46% -> #DIV/0! | U46: =R46/AJ46% -> #DIV/0! | V46: =T46-U46 -> #DIV/0! | Y46: =(W46-X46)/W46% -> #DIV/0! | Z46: =W46/AO46% -> #DIV/0! | AA46: =X46/AP46% -> #DIV/0! | AB46: =Z46-AA46 -> #DIV/0! | AE46: =(AC46-AD46)/AC46% -> #DIV/0! | AF46: =AC46/AU46% -> #DIV/0! | AG46: =AD46/AV46% -> #DIV/0! | AH46: =AF46-AG46 -> #DIV/0! | AI46: =D46+K46+Q46+W46+AC46 -> 0 | AJ46: =E46+L46+R46+X46+AD46 -> 0 | AK46: =(AI46-AJ46)/AJ46% -> #DIV/0!
C47: Raipur | D47: =D5+D26 -> 0 | E47: =E5+E26 -> 0 | F47: =(D47-E47)/E47% -> #DIV/0! | G47: =D47/AI47% -> #DIV/0! | H47: =E47/AJ47% -> #DIV/0! | I47: =G47-H47 -> #DIV/0! | J47: =((D47*AJ47)-(AI47*E47))/(AJ47-E47) -> #DIV/0! | K47: =K5+K26 -> 0 | L47: =L5+L26 -> 0 | M47: =(K47-L47)/L47% -> #DIV/0! | N47: =K47/AI47% -> #DIV/0! | O47: =L47/AJ47% -> #DIV/0! | P47: =N47-O47 -> #DIV/0! | Q47: =Q5+Q26 -> 0 | R47: =R5+R26 -> 0 | S47: =(Q47-R47)/Q47% -> #DIV/0! | T47: =Q47/AI47% -> #DIV/0! | U47: =R47/AJ47% -> #DIV/0! | V47: =T47-U47 -> #DIV/0! | Y47: =(W47-X47)/W47% -> #DIV/0! | Z47: =W47/AO47% -> #DIV/0! | AA47: =X47/AP47% -> #DIV/0! | AB47: =Z47-AA47 -> #DIV/0! | AE47: =(AC47-AD47)/AC47% -> #DIV/0! | AF47: =AC47/AU47% -> #DIV/0! | AG47: =AD47/AV47% -> #DIV/0! | AH47: =AF47-AG47 -> #DIV/0! | AI47: =D47+K47+Q47+W47+AC47 -> 0 | AJ47: =E47+L47+R47+X47+AD47 -> 0 | AK47: =(AI47-AJ47)/AJ47% -> #DIV/0!
...

Sheet SA Wise MKT

Sheet Sheet1
A1: OMC | B1: Dealer | C1: MS | J1: HSD
C2: Vol. 2024-25 | D2: Vol. 2025-26 | E2: Vol +/- | F2: Gr% | G2: % MKT Sh 2025-26 | H2: % MKT Sh 2024-25 | I2: MKT Sh +/- | J2: Vol. 2024-25 | K2: Vol. 2025-26 | L2: Vol +/- | M2: Gr% | N2: % MKT Sh 2025-26 | O2: % MKT Sh 2024-25 | P2: MKT Sh +/-
A3: HPC | B3: RAIPUR FUELS | C3: 806.5 | D3: 831 | E3: =D3-C3 -> 24.5 | F3: =E3/C3% -> 3.0378177 | G3: =D3/$D$8% -> 21.511778 | H3: =C3/$C$8% -> 20.594995 | I3: =G3-H3 -> 0.91678352 | J3: 483.5 | K3: 439 | L3: =K3-J3 -> -44.5 | M3: =L3/J3% -> -9.2037229 | N3: =K3/$K$8% -> 40.761374 | O3: =J3/$J$8% -> 41.609294 | P3: =N3-O3 -> -0.84792013
A4: HPC | B4: ADHOC SAI BABA FILLING STATION | C4: 540 | D4: 570 | E4: =D4-C4 -> 30 | F4: =E4/C4% -> 5.5555556 | G4: =D4/$D$8% -> 14.755371 | H4: =C4/$C$8% -> 13.789581 | I4: =G4-H4 -> 0.96579027 | J4: 136 | K4: 150 | L4: =K4-J4 -> 14 | M4: =L4/J4% -> 10.294118 | N4: =K4/$K$8% -> 13.927577 | O4: =J4/$J$8% -> 11.703959 | P4: =N4-O4 -> 2.2236179
A5: BPC | B5: TOP UP CENTER | C5: 1132 | D5: 1156 | E5: =D5-C5 -> 24 | F5: =E5/C5% -> 2.1201413 | G5: =D5/$D$8% -> 29.924929 | H5: =C5/$C$8% -> 28.907048 | I5: =G5-H5 -> 1.0178808 | J5: 0 | K5: 0 | L5: =K5-J5 -> 0 | M5: =L5/J5% -> #DIV/0! | N5: =K5/$K$8% -> 0 | O5: =J5/$J$8% -> 0 | P5: =N5-O5 -> 0
A6: BPC | B6: F.R FUELS | C6: 1159.5 | D6: 1044 | E6: =D6-C6 -> -115.5 | F6: =E6/C6% -> -9.9611902 | G6: =D6/$D$8% -> 27.025628 | H6: =C6/$C$8% -> 29.609295 | I6: =G6-H6 -> -2.5836674 | J6: 392.5 | K6: 324 | L6: =K6-J6 -> -68.5 | M6: =L6/J6% -> -17.452229 | N6: =K6/$K$8% -> 30.083565 | O6: =J6/$J$8% -> 33.777969 | P6: =N6-O6 -> -3.6944036
A7: IOC | B7: SHIVANSH FUELS | C7: 278 | D7: 262 | E7: =D7-C7 -> -16 | F7: =E7/C7% -> -5.7553957 | G7: =D7/$D$8% -> 6.7822936 | H7: =C7/$C$8% -> 7.0990807 | I7: =G7-H7 -> -0.31678714 | J7: 150 | K7: 164 | L7: =K7-J7 -> 14 | M7: =L7/J7% -> 9.3333333 | N7: =K7/$K$8% -> 15.227484 | O7: =J7/$J$8% -> 12.908778 | P7: =N7-O7 -> 2.3187058
A8: TA | B8: CEN_RAIPUR_RAIPUR-1_AMANAKA | C8: =SUM(C3:C7) -> 3916 | D8: =SUM(D3:D7) -> 3863 | E8: =D8-C8 -> -53 | F8: =E8/C8% -> -1.3534219 | G8: =D8/$D$8% -> 100 | H8: =C8/$C$8% -> 100 | I8: =G8-H8 -> 0 | J8: =SUM(J3:J7) -> 1162 | K8: =SUM(K3:K7) -> 1077 | L8: =K8-J8 -> -85 | M8: =L8/J8% -> -7.3149742 | N8: =K8/$K$8% -> 100 | O8: =J8/$J$8% -> 100 | P8: =N8-O8 -> 0
A12: OMC | B12: Dealer | C12: MS | J12: HSD
C13: Vol | D13: Vol | E13: Vol +/- | F13: % Gr | G13: % Mkt Sh | H13: % Mkt Sh | I13: Mkt Share | J13: Vol | K13: Vol | L13: Vol +/- | M13: % Gr | N13: % Mkt Sh | O13: % Mkt Sh | P13: Mkt Share
C14: 24-25 | D14: 25-26 | E14: 25-26 | F14: 25-26 | G14: 25-26 | H14: 24-25 | I14: +/- | J14: 24-25 | K14: 25-26 | L14: 25-26 | M14: 25-26 | N14: 25-26 | O14: 24-25 | P14: +/-
A15: HPC | B15: BHAVANI SERVICE STATION | C15: 23 | D15: 35 | E15: 12 | F15: 54.98 | G15: 10.85 | H15: 7.5 | I15: 3.35 | J15: 32 | K15: 45 | L15: 13 | M15: 40.99 | N15: 7.46 | O15: 5.24 | P15: 2.22
A16: HPC | B16: SHREE BALAJI SERVICE STATION | C16: 0 | D16: 0 | J16: 0 | K16: 0
A17: BPC | B17: VARDHMAN HIGHWAY SERVICE | C17: 28 | D17: 24.5 | E17: -4 | F17: -12.89 | G17: 7.6 | H17: 9.34 | I17: -1.75 | J17: 46 | K17: 49.5 | L17: 3 | M17: 7.32 | N17: 8.2 | O17: 7.57 | P17: 0.63
A18: IOC | B18: TCI | C18: 85 | D18: 81 | E18: -4 | F18: -5.08 | G18: 25.12 | H18: 28.35 | I18: -3.23 | J18: 275 | K18: 267 | L18: -8 | M18: -3.06 | N18: 44.24 | O18: 45.19 | P18: -0.95
A19: JIO BP | B19: DEVASHISH CHARODA | C19: 165 | D19: 182 | E19: 17 | F19: 10.3 | G19: 56.43 | H19: 54.81 | I19: 1.62 | J19: 256 | K19: 242 | L19: -14 | M19: -5.47 | N19: 40.1 | O19: 42 | P19: -1.91
A20: TA AREA | B20: NH53 LHS DURG-RPR | C20: 301 | D20: 323 | E20: 21 | F20: 7.13 | G20: 100 | H20: 100 | J20: 609 | K20: 604 | L20: -6 | M20: -0.98 | N20: 100 | O20: 100

Sheet Sheet8
A1: OMCs in Raipur | B1: Network (30.06.25) | C1: Avg TMF in KL | D1: TPO in KL | E1: Market Share
A2: HPC | B2: 379 | C2: =G2/3 -> 50075.333 | D2: =Table1[[#This Row],[Avg TMF in KL ]]/Table1[[#This Row],[Network (30.06.25) ]] -> 132.12489 | E2: 32.544327 | G2: 150226
A3: BPC | B3: 338 | C3: =G3/3 -> 48463.905 | D3: =Table1[[#This Row],[Avg TMF in KL ]]/Table1[[#This Row],[Network (30.06.25) ]] -> 143.38433 | E3: 31.497048 | G3: 145391.71 | H3: =G3/3 -> 48463.905
A4: IOC | B4: 428 | C4: =G4/3 -> 55328.849 | D4: =Table1[[#This Row],[Avg TMF in KL ]]/Table1[[#This Row],[Network (30.06.25) ]] -> 129.27301 | E4: 35.958626 | G4: 165986.55
A5: TOTAl | B5: =SUM(B2:B4) -> 1145 | C5: =G5/3 -> 153868.09 | D5: =Table1[[#This Row],[Avg TMF in KL ]]/Table1[[#This Row],[Network (30.06.25) ]] -> 134.38261 | G5: =SUM(G2:G4) -> 461604.26
D15: Difrence | E15: MS | F15: HSD
D16: Durg | E16: 0 | F16: 4
